2024-10-13 20:25:02,010 - minutememo_app.app - ERROR - Exception on /api/sessions/165 [GET]
Traceback (most recent call last):
  File "/Users/gaetanbuelinckx/minutememo_app/venv/lib/python3.12/site-packages/flask/app.py", line 1473, in wsgi_app
    response = self.full_dispatch_request()
               ^^^^^^^^^^^^^^^^^^^^^^^^^^^^
  File "/Users/gaetanbuelinckx/minutememo_app/venv/lib/python3.12/site-packages/flask/app.py", line 882, in full_dispatch_request
    rv = self.handle_user_exception(e)
         ^^^^^^^^^^^^^^^^^^^^^^^^^^^^^
  File "/Users/gaetanbuelinckx/minutememo_app/venv/lib/python3.12/site-packages/flask_cors/extension.py", line 178, in wrapped_function
    return cors_after_request(app.make_response(f(*args, **kwargs)))
                                                ^^^^^^^^^^^^^^^^^^
  File "/Users/gaetanbuelinckx/minutememo_app/venv/lib/python3.12/site-packages/flask/app.py", line 880, in full_dispatch_request
    rv = self.dispatch_request()
         ^^^^^^^^^^^^^^^^^^^^^^^
  File "/Users/gaetanbuelinckx/minutememo_app/venv/lib/python3.12/site-packages/flask/app.py", line 865, in dispatch_request
    return self.ensure_sync(self.view_functions[rule.endpoint])(**view_args)  # type: ignore[no-any-return]
           ^^^^^^^^^^^^^^^^^^^^^^^^^^^^^^^^^^^^^^^^^^^^^^^^^^^^^^^^^^^^^^^^^
  File "/Users/gaetanbuelinckx/minutememo_app/venv/lib/python3.12/site-packages/flask_login/utils.py", line 284, in decorated_view
    elif not current_user.is_authenticated:
             ^^^^^^^^^^^^^^^^^^^^^^^^^^^^^
  File "/Users/gaetanbuelinckx/minutememo_app/venv/lib/python3.12/site-packages/werkzeug/local.py", line 318, in __get__
    obj = instance._get_current_object()
          ^^^^^^^^^^^^^^^^^^^^^^^^^^^^^^
  File "/Users/gaetanbuelinckx/minutememo_app/venv/lib/python3.12/site-packages/werkzeug/local.py", line 526, in _get_current_object
    return get_name(local())
                    ^^^^^^^
  File "/Users/gaetanbuelinckx/minutememo_app/venv/lib/python3.12/site-packages/flask_login/utils.py", line 25, in <lambda>
    current_user = LocalProxy(lambda: _get_user())
                                      ^^^^^^^^^^^
  File "/Users/gaetanbuelinckx/minutememo_app/venv/lib/python3.12/site-packages/flask_login/utils.py", line 370, in _get_user
    current_app.login_manager._load_user()
  File "/Users/gaetanbuelinckx/minutememo_app/venv/lib/python3.12/site-packages/flask_login/login_manager.py", line 364, in _load_user
    user = self._user_callback(user_id)
           ^^^^^^^^^^^^^^^^^^^^^^^^^^^^
  File "/Users/gaetanbuelinckx/minutememo_app/app.py", line 108, in load_user
    return User.query.get(int(user_id))
           ^^^^^^^^^^
  File "/Users/gaetanbuelinckx/minutememo_app/venv/lib/python3.12/site-packages/flask_sqlalchemy/model.py", line 22, in __get__
    return cls.query_class(
           ^^^^^^^^^^^^^^^^
  File "/Users/gaetanbuelinckx/minutememo_app/venv/lib/python3.12/site-packages/sqlalchemy/orm/query.py", line 275, in __init__
    self._set_entities(entities)
  File "/Users/gaetanbuelinckx/minutememo_app/venv/lib/python3.12/site-packages/sqlalchemy/orm/query.py", line 288, in _set_entities
    coercions.expect(
  File "/Users/gaetanbuelinckx/minutememo_app/venv/lib/python3.12/site-packages/sqlalchemy/sql/coercions.py", line 389, in expect
    insp._post_inspect
  File "/Users/gaetanbuelinckx/minutememo_app/venv/lib/python3.12/site-packages/sqlalchemy/util/langhelpers.py", line 1253, in __get__
    obj.__dict__[self.__name__] = result = self.fget(obj)
                                           ^^^^^^^^^^^^^^
  File "/Users/gaetanbuelinckx/minutememo_app/venv/lib/python3.12/site-packages/sqlalchemy/orm/mapper.py", line 2711, in _post_inspect
    self._check_configure()
  File "/Users/gaetanbuelinckx/minutememo_app/venv/lib/python3.12/site-packages/sqlalchemy/orm/mapper.py", line 2388, in _check_configure
    _configure_registries({self.registry}, cascade=True)
  File "/Users/gaetanbuelinckx/minutememo_app/venv/lib/python3.12/site-packages/sqlalchemy/orm/mapper.py", line 4204, in _configure_registries
    _do_configure_registries(registries, cascade)
  File "/Users/gaetanbuelinckx/minutememo_app/venv/lib/python3.12/site-packages/sqlalchemy/orm/mapper.py", line 4241, in _do_configure_registries
    raise e
sqlalchemy.exc.InvalidRequestError: One or more mappers failed to initialize - can't proceed with initialization of other mappers. Triggering mapper: 'Mapper[User(user)]'. Original exception was: When initializing mapper Mapper[User(user)], expression 'meeting_participants' failed to locate a name ("name 'meeting_participants' is not defined"). If this is a class name, consider adding this relationship() to the <class 'models.User'> class after both dependent classes have been defined.
2024-10-13 20:25:02,011 - minutememo_app.app - ERROR - Exception on /api/meetinghubs [GET]
Traceback (most recent call last):
  File "/Users/gaetanbuelinckx/minutememo_app/venv/lib/python3.12/site-packages/flask/app.py", line 1473, in wsgi_app
    response = self.full_dispatch_request()
               ^^^^^^^^^^^^^^^^^^^^^^^^^^^^
  File "/Users/gaetanbuelinckx/minutememo_app/venv/lib/python3.12/site-packages/flask/app.py", line 882, in full_dispatch_request
    rv = self.handle_user_exception(e)
         ^^^^^^^^^^^^^^^^^^^^^^^^^^^^^
  File "/Users/gaetanbuelinckx/minutememo_app/venv/lib/python3.12/site-packages/flask_cors/extension.py", line 178, in wrapped_function
    return cors_after_request(app.make_response(f(*args, **kwargs)))
                                                ^^^^^^^^^^^^^^^^^^
  File "/Users/gaetanbuelinckx/minutememo_app/venv/lib/python3.12/site-packages/flask/app.py", line 880, in full_dispatch_request
    rv = self.dispatch_request()
         ^^^^^^^^^^^^^^^^^^^^^^^
  File "/Users/gaetanbuelinckx/minutememo_app/venv/lib/python3.12/site-packages/flask/app.py", line 865, in dispatch_request
    return self.ensure_sync(self.view_functions[rule.endpoint])(**view_args)  # type: ignore[no-any-return]
           ^^^^^^^^^^^^^^^^^^^^^^^^^^^^^^^^^^^^^^^^^^^^^^^^^^^^^^^^^^^^^^^^^
  File "/Users/gaetanbuelinckx/minutememo_app/venv/lib/python3.12/site-packages/flask_login/utils.py", line 284, in decorated_view
    elif not current_user.is_authenticated:
             ^^^^^^^^^^^^^^^^^^^^^^^^^^^^^
  File "/Users/gaetanbuelinckx/minutememo_app/venv/lib/python3.12/site-packages/werkzeug/local.py", line 318, in __get__
    obj = instance._get_current_object()
          ^^^^^^^^^^^^^^^^^^^^^^^^^^^^^^
  File "/Users/gaetanbuelinckx/minutememo_app/venv/lib/python3.12/site-packages/werkzeug/local.py", line 526, in _get_current_object
    return get_name(local())
                    ^^^^^^^
  File "/Users/gaetanbuelinckx/minutememo_app/venv/lib/python3.12/site-packages/flask_login/utils.py", line 25, in <lambda>
    current_user = LocalProxy(lambda: _get_user())
                                      ^^^^^^^^^^^
  File "/Users/gaetanbuelinckx/minutememo_app/venv/lib/python3.12/site-packages/flask_login/utils.py", line 370, in _get_user
    current_app.login_manager._load_user()
  File "/Users/gaetanbuelinckx/minutememo_app/venv/lib/python3.12/site-packages/flask_login/login_manager.py", line 364, in _load_user
    user = self._user_callback(user_id)
           ^^^^^^^^^^^^^^^^^^^^^^^^^^^^
  File "/Users/gaetanbuelinckx/minutememo_app/app.py", line 108, in load_user
    return User.query.get(int(user_id))
           ^^^^^^^^^^
  File "/Users/gaetanbuelinckx/minutememo_app/venv/lib/python3.12/site-packages/flask_sqlalchemy/model.py", line 22, in __get__
    return cls.query_class(
           ^^^^^^^^^^^^^^^^
  File "/Users/gaetanbuelinckx/minutememo_app/venv/lib/python3.12/site-packages/sqlalchemy/orm/query.py", line 275, in __init__
    self._set_entities(entities)
  File "/Users/gaetanbuelinckx/minutememo_app/venv/lib/python3.12/site-packages/sqlalchemy/orm/query.py", line 288, in _set_entities
    coercions.expect(
  File "/Users/gaetanbuelinckx/minutememo_app/venv/lib/python3.12/site-packages/sqlalchemy/sql/coercions.py", line 389, in expect
    insp._post_inspect
  File "/Users/gaetanbuelinckx/minutememo_app/venv/lib/python3.12/site-packages/sqlalchemy/util/langhelpers.py", line 1253, in __get__
    obj.__dict__[self.__name__] = result = self.fget(obj)
                                           ^^^^^^^^^^^^^^
  File "/Users/gaetanbuelinckx/minutememo_app/venv/lib/python3.12/site-packages/sqlalchemy/orm/mapper.py", line 2711, in _post_inspect
    self._check_configure()
  File "/Users/gaetanbuelinckx/minutememo_app/venv/lib/python3.12/site-packages/sqlalchemy/orm/mapper.py", line 2388, in _check_configure
    _configure_registries({self.registry}, cascade=True)
  File "/Users/gaetanbuelinckx/minutememo_app/venv/lib/python3.12/site-packages/sqlalchemy/orm/mapper.py", line 4204, in _configure_registries
    _do_configure_registries(registries, cascade)
  File "/Users/gaetanbuelinckx/minutememo_app/venv/lib/python3.12/site-packages/sqlalchemy/orm/mapper.py", line 4241, in _do_configure_registries
    raise e
sqlalchemy.exc.InvalidRequestError: One or more mappers failed to initialize - can't proceed with initialization of other mappers. Triggering mapper: 'Mapper[User(user)]'. Original exception was: When initializing mapper Mapper[User(user)], expression 'meeting_participants' failed to locate a name ("name 'meeting_participants' is not defined"). If this is a class name, consider adding this relationship() to the <class 'models.User'> class after both dependent classes have been defined.
2024-10-13 20:25:02,012 - minutememo_app.app - ERROR - Exception on /api/calendar/events [GET]
Traceback (most recent call last):
  File "/Users/gaetanbuelinckx/minutememo_app/venv/lib/python3.12/site-packages/flask/app.py", line 1473, in wsgi_app
    response = self.full_dispatch_request()
               ^^^^^^^^^^^^^^^^^^^^^^^^^^^^
  File "/Users/gaetanbuelinckx/minutememo_app/venv/lib/python3.12/site-packages/flask/app.py", line 882, in full_dispatch_request
    rv = self.handle_user_exception(e)
         ^^^^^^^^^^^^^^^^^^^^^^^^^^^^^
  File "/Users/gaetanbuelinckx/minutememo_app/venv/lib/python3.12/site-packages/flask_cors/extension.py", line 178, in wrapped_function
    return cors_after_request(app.make_response(f(*args, **kwargs)))
                                                ^^^^^^^^^^^^^^^^^^
  File "/Users/gaetanbuelinckx/minutememo_app/venv/lib/python3.12/site-packages/flask/app.py", line 880, in full_dispatch_request
    rv = self.dispatch_request()
         ^^^^^^^^^^^^^^^^^^^^^^^
  File "/Users/gaetanbuelinckx/minutememo_app/venv/lib/python3.12/site-packages/flask/app.py", line 865, in dispatch_request
    return self.ensure_sync(self.view_functions[rule.endpoint])(**view_args)  # type: ignore[no-any-return]
           ^^^^^^^^^^^^^^^^^^^^^^^^^^^^^^^^^^^^^^^^^^^^^^^^^^^^^^^^^^^^^^^^^
  File "/Users/gaetanbuelinckx/minutememo_app/venv/lib/python3.12/site-packages/flask_login/utils.py", line 284, in decorated_view
    elif not current_user.is_authenticated:
             ^^^^^^^^^^^^^^^^^^^^^^^^^^^^^
  File "/Users/gaetanbuelinckx/minutememo_app/venv/lib/python3.12/site-packages/werkzeug/local.py", line 318, in __get__
    obj = instance._get_current_object()
          ^^^^^^^^^^^^^^^^^^^^^^^^^^^^^^
  File "/Users/gaetanbuelinckx/minutememo_app/venv/lib/python3.12/site-packages/werkzeug/local.py", line 526, in _get_current_object
    return get_name(local())
                    ^^^^^^^
  File "/Users/gaetanbuelinckx/minutememo_app/venv/lib/python3.12/site-packages/flask_login/utils.py", line 25, in <lambda>
    current_user = LocalProxy(lambda: _get_user())
                                      ^^^^^^^^^^^
  File "/Users/gaetanbuelinckx/minutememo_app/venv/lib/python3.12/site-packages/flask_login/utils.py", line 370, in _get_user
    current_app.login_manager._load_user()
  File "/Users/gaetanbuelinckx/minutememo_app/venv/lib/python3.12/site-packages/flask_login/login_manager.py", line 364, in _load_user
    user = self._user_callback(user_id)
           ^^^^^^^^^^^^^^^^^^^^^^^^^^^^
  File "/Users/gaetanbuelinckx/minutememo_app/app.py", line 108, in load_user
    return User.query.get(int(user_id))
           ^^^^^^^^^^
  File "/Users/gaetanbuelinckx/minutememo_app/venv/lib/python3.12/site-packages/flask_sqlalchemy/model.py", line 22, in __get__
    return cls.query_class(
           ^^^^^^^^^^^^^^^^
  File "/Users/gaetanbuelinckx/minutememo_app/venv/lib/python3.12/site-packages/sqlalchemy/orm/query.py", line 275, in __init__
    self._set_entities(entities)
  File "/Users/gaetanbuelinckx/minutememo_app/venv/lib/python3.12/site-packages/sqlalchemy/orm/query.py", line 288, in _set_entities
    coercions.expect(
  File "/Users/gaetanbuelinckx/minutememo_app/venv/lib/python3.12/site-packages/sqlalchemy/sql/coercions.py", line 389, in expect
    insp._post_inspect
  File "/Users/gaetanbuelinckx/minutememo_app/venv/lib/python3.12/site-packages/sqlalchemy/util/langhelpers.py", line 1253, in __get__
    obj.__dict__[self.__name__] = result = self.fget(obj)
                                           ^^^^^^^^^^^^^^
  File "/Users/gaetanbuelinckx/minutememo_app/venv/lib/python3.12/site-packages/sqlalchemy/orm/mapper.py", line 2711, in _post_inspect
    self._check_configure()
  File "/Users/gaetanbuelinckx/minutememo_app/venv/lib/python3.12/site-packages/sqlalchemy/orm/mapper.py", line 2388, in _check_configure
    _configure_registries({self.registry}, cascade=True)
  File "/Users/gaetanbuelinckx/minutememo_app/venv/lib/python3.12/site-packages/sqlalchemy/orm/mapper.py", line 4204, in _configure_registries
    _do_configure_registries(registries, cascade)
  File "/Users/gaetanbuelinckx/minutememo_app/venv/lib/python3.12/site-packages/sqlalchemy/orm/mapper.py", line 4241, in _do_configure_registries
    raise e
sqlalchemy.exc.InvalidRequestError: One or more mappers failed to initialize - can't proceed with initialization of other mappers. Triggering mapper: 'Mapper[User(user)]'. Original exception was: When initializing mapper Mapper[User(user)], expression 'meeting_participants' failed to locate a name ("name 'meeting_participants' is not defined"). If this is a class name, consider adding this relationship() to the <class 'models.User'> class after both dependent classes have been defined.
2024-10-13 20:25:02,017 - auth - DEBUG - After request, Origin: http://localhost:3000
2024-10-13 20:25:02,017 - auth - DEBUG - After request, Origin: http://localhost:3000
2024-10-13 20:25:02,017 - auth - DEBUG - After request, Origin: http://localhost:3000
2024-10-13 20:25:02,018 - werkzeug - INFO - 127.0.0.1 - - [13/Oct/2024 20:25:02] "[35m[1mGET /api/sessions/165 HTTP/1.1[0m" 500 -
2024-10-13 20:25:02,019 - werkzeug - INFO - 127.0.0.1 - - [13/Oct/2024 20:25:02] "[35m[1mGET /api/calendar/events HTTP/1.1[0m" 500 -
2024-10-13 20:25:02,019 - werkzeug - INFO - 127.0.0.1 - - [13/Oct/2024 20:25:02] "[35m[1mGET /api/meetinghubs HTTP/1.1[0m" 500 -
2024-10-13 20:25:02,023 - minutememo_app.app - ERROR - Exception on /api/meetinghubs [GET]
Traceback (most recent call last):
  File "/Users/gaetanbuelinckx/minutememo_app/venv/lib/python3.12/site-packages/flask/app.py", line 1473, in wsgi_app
    response = self.full_dispatch_request()
               ^^^^^^^^^^^^^^^^^^^^^^^^^^^^
  File "/Users/gaetanbuelinckx/minutememo_app/venv/lib/python3.12/site-packages/flask/app.py", line 882, in full_dispatch_request
    rv = self.handle_user_exception(e)
         ^^^^^^^^^^^^^^^^^^^^^^^^^^^^^
  File "/Users/gaetanbuelinckx/minutememo_app/venv/lib/python3.12/site-packages/flask_cors/extension.py", line 178, in wrapped_function
    return cors_after_request(app.make_response(f(*args, **kwargs)))
                                                ^^^^^^^^^^^^^^^^^^
  File "/Users/gaetanbuelinckx/minutememo_app/venv/lib/python3.12/site-packages/flask/app.py", line 880, in full_dispatch_request
    rv = self.dispatch_request()
         ^^^^^^^^^^^^^^^^^^^^^^^
  File "/Users/gaetanbuelinckx/minutememo_app/venv/lib/python3.12/site-packages/flask/app.py", line 865, in dispatch_request
    return self.ensure_sync(self.view_functions[rule.endpoint])(**view_args)  # type: ignore[no-any-return]
           ^^^^^^^^^^^^^^^^^^^^^^^^^^^^^^^^^^^^^^^^^^^^^^^^^^^^^^^^^^^^^^^^^
  File "/Users/gaetanbuelinckx/minutememo_app/venv/lib/python3.12/site-packages/flask_login/utils.py", line 284, in decorated_view
    elif not current_user.is_authenticated:
             ^^^^^^^^^^^^^^^^^^^^^^^^^^^^^
  File "/Users/gaetanbuelinckx/minutememo_app/venv/lib/python3.12/site-packages/werkzeug/local.py", line 318, in __get__
    obj = instance._get_current_object()
          ^^^^^^^^^^^^^^^^^^^^^^^^^^^^^^
  File "/Users/gaetanbuelinckx/minutememo_app/venv/lib/python3.12/site-packages/werkzeug/local.py", line 526, in _get_current_object
    return get_name(local())
                    ^^^^^^^
  File "/Users/gaetanbuelinckx/minutememo_app/venv/lib/python3.12/site-packages/flask_login/utils.py", line 25, in <lambda>
    current_user = LocalProxy(lambda: _get_user())
                                      ^^^^^^^^^^^
  File "/Users/gaetanbuelinckx/minutememo_app/venv/lib/python3.12/site-packages/flask_login/utils.py", line 370, in _get_user
    current_app.login_manager._load_user()
  File "/Users/gaetanbuelinckx/minutememo_app/venv/lib/python3.12/site-packages/flask_login/login_manager.py", line 364, in _load_user
    user = self._user_callback(user_id)
           ^^^^^^^^^^^^^^^^^^^^^^^^^^^^
  File "/Users/gaetanbuelinckx/minutememo_app/app.py", line 108, in load_user
    return User.query.get(int(user_id))
           ^^^^^^^^^^
  File "/Users/gaetanbuelinckx/minutememo_app/venv/lib/python3.12/site-packages/flask_sqlalchemy/model.py", line 22, in __get__
    return cls.query_class(
           ^^^^^^^^^^^^^^^^
  File "/Users/gaetanbuelinckx/minutememo_app/venv/lib/python3.12/site-packages/sqlalchemy/orm/query.py", line 275, in __init__
    self._set_entities(entities)
  File "/Users/gaetanbuelinckx/minutememo_app/venv/lib/python3.12/site-packages/sqlalchemy/orm/query.py", line 288, in _set_entities
    coercions.expect(
  File "/Users/gaetanbuelinckx/minutememo_app/venv/lib/python3.12/site-packages/sqlalchemy/sql/coercions.py", line 389, in expect
    insp._post_inspect
  File "/Users/gaetanbuelinckx/minutememo_app/venv/lib/python3.12/site-packages/sqlalchemy/util/langhelpers.py", line 1253, in __get__
    obj.__dict__[self.__name__] = result = self.fget(obj)
                                           ^^^^^^^^^^^^^^
  File "/Users/gaetanbuelinckx/minutememo_app/venv/lib/python3.12/site-packages/sqlalchemy/orm/mapper.py", line 2711, in _post_inspect
    self._check_configure()
  File "/Users/gaetanbuelinckx/minutememo_app/venv/lib/python3.12/site-packages/sqlalchemy/orm/mapper.py", line 2388, in _check_configure
    _configure_registries({self.registry}, cascade=True)
  File "/Users/gaetanbuelinckx/minutememo_app/venv/lib/python3.12/site-packages/sqlalchemy/orm/mapper.py", line 4204, in _configure_registries
    _do_configure_registries(registries, cascade)
  File "/Users/gaetanbuelinckx/minutememo_app/venv/lib/python3.12/site-packages/sqlalchemy/orm/mapper.py", line 4241, in _do_configure_registries
    raise e
sqlalchemy.exc.InvalidRequestError: One or more mappers failed to initialize - can't proceed with initialization of other mappers. Triggering mapper: 'Mapper[User(user)]'. Original exception was: When initializing mapper Mapper[User(user)], expression 'meeting_participants' failed to locate a name ("name 'meeting_participants' is not defined"). If this is a class name, consider adding this relationship() to the <class 'models.User'> class after both dependent classes have been defined.
2024-10-13 20:25:02,024 - minutememo_app.app - ERROR - Exception on /api/calendar/events [GET]
Traceback (most recent call last):
  File "/Users/gaetanbuelinckx/minutememo_app/venv/lib/python3.12/site-packages/flask/app.py", line 1473, in wsgi_app
    response = self.full_dispatch_request()
               ^^^^^^^^^^^^^^^^^^^^^^^^^^^^
  File "/Users/gaetanbuelinckx/minutememo_app/venv/lib/python3.12/site-packages/flask/app.py", line 882, in full_dispatch_request
    rv = self.handle_user_exception(e)
         ^^^^^^^^^^^^^^^^^^^^^^^^^^^^^
  File "/Users/gaetanbuelinckx/minutememo_app/venv/lib/python3.12/site-packages/flask_cors/extension.py", line 178, in wrapped_function
    return cors_after_request(app.make_response(f(*args, **kwargs)))
                                                ^^^^^^^^^^^^^^^^^^
  File "/Users/gaetanbuelinckx/minutememo_app/venv/lib/python3.12/site-packages/flask/app.py", line 880, in full_dispatch_request
    rv = self.dispatch_request()
         ^^^^^^^^^^^^^^^^^^^^^^^
  File "/Users/gaetanbuelinckx/minutememo_app/venv/lib/python3.12/site-packages/flask/app.py", line 865, in dispatch_request
    return self.ensure_sync(self.view_functions[rule.endpoint])(**view_args)  # type: ignore[no-any-return]
           ^^^^^^^^^^^^^^^^^^^^^^^^^^^^^^^^^^^^^^^^^^^^^^^^^^^^^^^^^^^^^^^^^
  File "/Users/gaetanbuelinckx/minutememo_app/venv/lib/python3.12/site-packages/flask_login/utils.py", line 284, in decorated_view
    elif not current_user.is_authenticated:
             ^^^^^^^^^^^^^^^^^^^^^^^^^^^^^
  File "/Users/gaetanbuelinckx/minutememo_app/venv/lib/python3.12/site-packages/werkzeug/local.py", line 318, in __get__
    obj = instance._get_current_object()
          ^^^^^^^^^^^^^^^^^^^^^^^^^^^^^^
  File "/Users/gaetanbuelinckx/minutememo_app/venv/lib/python3.12/site-packages/werkzeug/local.py", line 526, in _get_current_object
    return get_name(local())
                    ^^^^^^^
  File "/Users/gaetanbuelinckx/minutememo_app/venv/lib/python3.12/site-packages/flask_login/utils.py", line 25, in <lambda>
    current_user = LocalProxy(lambda: _get_user())
                                      ^^^^^^^^^^^
  File "/Users/gaetanbuelinckx/minutememo_app/venv/lib/python3.12/site-packages/flask_login/utils.py", line 370, in _get_user
    current_app.login_manager._load_user()
  File "/Users/gaetanbuelinckx/minutememo_app/venv/lib/python3.12/site-packages/flask_login/login_manager.py", line 364, in _load_user
    user = self._user_callback(user_id)
           ^^^^^^^^^^^^^^^^^^^^^^^^^^^^
  File "/Users/gaetanbuelinckx/minutememo_app/app.py", line 108, in load_user
    return User.query.get(int(user_id))
           ^^^^^^^^^^
  File "/Users/gaetanbuelinckx/minutememo_app/venv/lib/python3.12/site-packages/flask_sqlalchemy/model.py", line 22, in __get__
    return cls.query_class(
           ^^^^^^^^^^^^^^^^
  File "/Users/gaetanbuelinckx/minutememo_app/venv/lib/python3.12/site-packages/sqlalchemy/orm/query.py", line 275, in __init__
    self._set_entities(entities)
  File "/Users/gaetanbuelinckx/minutememo_app/venv/lib/python3.12/site-packages/sqlalchemy/orm/query.py", line 288, in _set_entities
    coercions.expect(
  File "/Users/gaetanbuelinckx/minutememo_app/venv/lib/python3.12/site-packages/sqlalchemy/sql/coercions.py", line 389, in expect
    insp._post_inspect
  File "/Users/gaetanbuelinckx/minutememo_app/venv/lib/python3.12/site-packages/sqlalchemy/util/langhelpers.py", line 1253, in __get__
    obj.__dict__[self.__name__] = result = self.fget(obj)
                                           ^^^^^^^^^^^^^^
  File "/Users/gaetanbuelinckx/minutememo_app/venv/lib/python3.12/site-packages/sqlalchemy/orm/mapper.py", line 2711, in _post_inspect
    self._check_configure()
  File "/Users/gaetanbuelinckx/minutememo_app/venv/lib/python3.12/site-packages/sqlalchemy/orm/mapper.py", line 2388, in _check_configure
    _configure_registries({self.registry}, cascade=True)
  File "/Users/gaetanbuelinckx/minutememo_app/venv/lib/python3.12/site-packages/sqlalchemy/orm/mapper.py", line 4204, in _configure_registries
    _do_configure_registries(registries, cascade)
  File "/Users/gaetanbuelinckx/minutememo_app/venv/lib/python3.12/site-packages/sqlalchemy/orm/mapper.py", line 4241, in _do_configure_registries
    raise e
sqlalchemy.exc.InvalidRequestError: One or more mappers failed to initialize - can't proceed with initialization of other mappers. Triggering mapper: 'Mapper[User(user)]'. Original exception was: When initializing mapper Mapper[User(user)], expression 'meeting_participants' failed to locate a name ("name 'meeting_participants' is not defined"). If this is a class name, consider adding this relationship() to the <class 'models.User'> class after both dependent classes have been defined.
2024-10-13 20:25:02,026 - minutememo_app.app - ERROR - Exception on /api/sessions/165 [GET]
Traceback (most recent call last):
  File "/Users/gaetanbuelinckx/minutememo_app/venv/lib/python3.12/site-packages/flask/app.py", line 1473, in wsgi_app
    response = self.full_dispatch_request()
               ^^^^^^^^^^^^^^^^^^^^^^^^^^^^
  File "/Users/gaetanbuelinckx/minutememo_app/venv/lib/python3.12/site-packages/flask/app.py", line 882, in full_dispatch_request
    rv = self.handle_user_exception(e)
         ^^^^^^^^^^^^^^^^^^^^^^^^^^^^^
  File "/Users/gaetanbuelinckx/minutememo_app/venv/lib/python3.12/site-packages/flask_cors/extension.py", line 178, in wrapped_function
    return cors_after_request(app.make_response(f(*args, **kwargs)))
                                                ^^^^^^^^^^^^^^^^^^
  File "/Users/gaetanbuelinckx/minutememo_app/venv/lib/python3.12/site-packages/flask/app.py", line 880, in full_dispatch_request
    rv = self.dispatch_request()
         ^^^^^^^^^^^^^^^^^^^^^^^
  File "/Users/gaetanbuelinckx/minutememo_app/venv/lib/python3.12/site-packages/flask/app.py", line 865, in dispatch_request
    return self.ensure_sync(self.view_functions[rule.endpoint])(**view_args)  # type: ignore[no-any-return]
           ^^^^^^^^^^^^^^^^^^^^^^^^^^^^^^^^^^^^^^^^^^^^^^^^^^^^^^^^^^^^^^^^^
  File "/Users/gaetanbuelinckx/minutememo_app/venv/lib/python3.12/site-packages/flask_login/utils.py", line 284, in decorated_view
    elif not current_user.is_authenticated:
             ^^^^^^^^^^^^^^^^^^^^^^^^^^^^^
  File "/Users/gaetanbuelinckx/minutememo_app/venv/lib/python3.12/site-packages/werkzeug/local.py", line 318, in __get__
    obj = instance._get_current_object()
          ^^^^^^^^^^^^^^^^^^^^^^^^^^^^^^
  File "/Users/gaetanbuelinckx/minutememo_app/venv/lib/python3.12/site-packages/werkzeug/local.py", line 526, in _get_current_object
    return get_name(local())
                    ^^^^^^^
  File "/Users/gaetanbuelinckx/minutememo_app/venv/lib/python3.12/site-packages/flask_login/utils.py", line 25, in <lambda>
    current_user = LocalProxy(lambda: _get_user())
                                      ^^^^^^^^^^^
  File "/Users/gaetanbuelinckx/minutememo_app/venv/lib/python3.12/site-packages/flask_login/utils.py", line 370, in _get_user
    current_app.login_manager._load_user()
  File "/Users/gaetanbuelinckx/minutememo_app/venv/lib/python3.12/site-packages/flask_login/login_manager.py", line 364, in _load_user
    user = self._user_callback(user_id)
           ^^^^^^^^^^^^^^^^^^^^^^^^^^^^
  File "/Users/gaetanbuelinckx/minutememo_app/app.py", line 108, in load_user
    return User.query.get(int(user_id))
           ^^^^^^^^^^
  File "/Users/gaetanbuelinckx/minutememo_app/venv/lib/python3.12/site-packages/flask_sqlalchemy/model.py", line 22, in __get__
    return cls.query_class(
           ^^^^^^^^^^^^^^^^
  File "/Users/gaetanbuelinckx/minutememo_app/venv/lib/python3.12/site-packages/sqlalchemy/orm/query.py", line 275, in __init__
    self._set_entities(entities)
  File "/Users/gaetanbuelinckx/minutememo_app/venv/lib/python3.12/site-packages/sqlalchemy/orm/query.py", line 288, in _set_entities
    coercions.expect(
  File "/Users/gaetanbuelinckx/minutememo_app/venv/lib/python3.12/site-packages/sqlalchemy/sql/coercions.py", line 389, in expect
    insp._post_inspect
  File "/Users/gaetanbuelinckx/minutememo_app/venv/lib/python3.12/site-packages/sqlalchemy/util/langhelpers.py", line 1253, in __get__
    obj.__dict__[self.__name__] = result = self.fget(obj)
                                           ^^^^^^^^^^^^^^
  File "/Users/gaetanbuelinckx/minutememo_app/venv/lib/python3.12/site-packages/sqlalchemy/orm/mapper.py", line 2711, in _post_inspect
    self._check_configure()
  File "/Users/gaetanbuelinckx/minutememo_app/venv/lib/python3.12/site-packages/sqlalchemy/orm/mapper.py", line 2388, in _check_configure
    _configure_registries({self.registry}, cascade=True)
  File "/Users/gaetanbuelinckx/minutememo_app/venv/lib/python3.12/site-packages/sqlalchemy/orm/mapper.py", line 4204, in _configure_registries
    _do_configure_registries(registries, cascade)
  File "/Users/gaetanbuelinckx/minutememo_app/venv/lib/python3.12/site-packages/sqlalchemy/orm/mapper.py", line 4241, in _do_configure_registries
    raise e
sqlalchemy.exc.InvalidRequestError: One or more mappers failed to initialize - can't proceed with initialization of other mappers. Triggering mapper: 'Mapper[User(user)]'. Original exception was: When initializing mapper Mapper[User(user)], expression 'meeting_participants' failed to locate a name ("name 'meeting_participants' is not defined"). If this is a class name, consider adding this relationship() to the <class 'models.User'> class after both dependent classes have been defined.
2024-10-13 20:25:02,028 - auth - DEBUG - After request, Origin: http://localhost:3000
2024-10-13 20:25:02,030 - auth - DEBUG - After request, Origin: http://localhost:3000
2024-10-13 20:25:02,031 - auth - DEBUG - After request, Origin: http://localhost:3000
2024-10-13 20:25:02,031 - werkzeug - INFO - 127.0.0.1 - - [13/Oct/2024 20:25:02] "[35m[1mGET /api/meetinghubs HTTP/1.1[0m" 500 -
2024-10-13 20:25:02,032 - werkzeug - INFO - 127.0.0.1 - - [13/Oct/2024 20:25:02] "[35m[1mGET /api/calendar/events HTTP/1.1[0m" 500 -
2024-10-13 20:25:02,032 - werkzeug - INFO - 127.0.0.1 - - [13/Oct/2024 20:25:02] "[35m[1mGET /api/sessions/165 HTTP/1.1[0m" 500 -
2024-10-13 20:25:02,035 - minutememo_app.app - ERROR - Exception on /api/sessions/165 [GET]
Traceback (most recent call last):
  File "/Users/gaetanbuelinckx/minutememo_app/venv/lib/python3.12/site-packages/flask/app.py", line 1473, in wsgi_app
    response = self.full_dispatch_request()
               ^^^^^^^^^^^^^^^^^^^^^^^^^^^^
  File "/Users/gaetanbuelinckx/minutememo_app/venv/lib/python3.12/site-packages/flask/app.py", line 882, in full_dispatch_request
    rv = self.handle_user_exception(e)
         ^^^^^^^^^^^^^^^^^^^^^^^^^^^^^
  File "/Users/gaetanbuelinckx/minutememo_app/venv/lib/python3.12/site-packages/flask_cors/extension.py", line 178, in wrapped_function
    return cors_after_request(app.make_response(f(*args, **kwargs)))
                                                ^^^^^^^^^^^^^^^^^^
  File "/Users/gaetanbuelinckx/minutememo_app/venv/lib/python3.12/site-packages/flask/app.py", line 880, in full_dispatch_request
    rv = self.dispatch_request()
         ^^^^^^^^^^^^^^^^^^^^^^^
  File "/Users/gaetanbuelinckx/minutememo_app/venv/lib/python3.12/site-packages/flask/app.py", line 865, in dispatch_request
    return self.ensure_sync(self.view_functions[rule.endpoint])(**view_args)  # type: ignore[no-any-return]
           ^^^^^^^^^^^^^^^^^^^^^^^^^^^^^^^^^^^^^^^^^^^^^^^^^^^^^^^^^^^^^^^^^
  File "/Users/gaetanbuelinckx/minutememo_app/venv/lib/python3.12/site-packages/flask_login/utils.py", line 284, in decorated_view
    elif not current_user.is_authenticated:
             ^^^^^^^^^^^^^^^^^^^^^^^^^^^^^
  File "/Users/gaetanbuelinckx/minutememo_app/venv/lib/python3.12/site-packages/werkzeug/local.py", line 318, in __get__
    obj = instance._get_current_object()
          ^^^^^^^^^^^^^^^^^^^^^^^^^^^^^^
  File "/Users/gaetanbuelinckx/minutememo_app/venv/lib/python3.12/site-packages/werkzeug/local.py", line 526, in _get_current_object
    return get_name(local())
                    ^^^^^^^
  File "/Users/gaetanbuelinckx/minutememo_app/venv/lib/python3.12/site-packages/flask_login/utils.py", line 25, in <lambda>
    current_user = LocalProxy(lambda: _get_user())
                                      ^^^^^^^^^^^
  File "/Users/gaetanbuelinckx/minutememo_app/venv/lib/python3.12/site-packages/flask_login/utils.py", line 370, in _get_user
    current_app.login_manager._load_user()
  File "/Users/gaetanbuelinckx/minutememo_app/venv/lib/python3.12/site-packages/flask_login/login_manager.py", line 364, in _load_user
    user = self._user_callback(user_id)
           ^^^^^^^^^^^^^^^^^^^^^^^^^^^^
  File "/Users/gaetanbuelinckx/minutememo_app/app.py", line 108, in load_user
    return User.query.get(int(user_id))
           ^^^^^^^^^^
  File "/Users/gaetanbuelinckx/minutememo_app/venv/lib/python3.12/site-packages/flask_sqlalchemy/model.py", line 22, in __get__
    return cls.query_class(
           ^^^^^^^^^^^^^^^^
  File "/Users/gaetanbuelinckx/minutememo_app/venv/lib/python3.12/site-packages/sqlalchemy/orm/query.py", line 275, in __init__
    self._set_entities(entities)
  File "/Users/gaetanbuelinckx/minutememo_app/venv/lib/python3.12/site-packages/sqlalchemy/orm/query.py", line 288, in _set_entities
    coercions.expect(
  File "/Users/gaetanbuelinckx/minutememo_app/venv/lib/python3.12/site-packages/sqlalchemy/sql/coercions.py", line 389, in expect
    insp._post_inspect
  File "/Users/gaetanbuelinckx/minutememo_app/venv/lib/python3.12/site-packages/sqlalchemy/util/langhelpers.py", line 1253, in __get__
    obj.__dict__[self.__name__] = result = self.fget(obj)
                                           ^^^^^^^^^^^^^^
  File "/Users/gaetanbuelinckx/minutememo_app/venv/lib/python3.12/site-packages/sqlalchemy/orm/mapper.py", line 2711, in _post_inspect
    self._check_configure()
  File "/Users/gaetanbuelinckx/minutememo_app/venv/lib/python3.12/site-packages/sqlalchemy/orm/mapper.py", line 2388, in _check_configure
    _configure_registries({self.registry}, cascade=True)
  File "/Users/gaetanbuelinckx/minutememo_app/venv/lib/python3.12/site-packages/sqlalchemy/orm/mapper.py", line 4204, in _configure_registries
    _do_configure_registries(registries, cascade)
  File "/Users/gaetanbuelinckx/minutememo_app/venv/lib/python3.12/site-packages/sqlalchemy/orm/mapper.py", line 4241, in _do_configure_registries
    raise e
sqlalchemy.exc.InvalidRequestError: One or more mappers failed to initialize - can't proceed with initialization of other mappers. Triggering mapper: 'Mapper[User(user)]'. Original exception was: When initializing mapper Mapper[User(user)], expression 'meeting_participants' failed to locate a name ("name 'meeting_participants' is not defined"). If this is a class name, consider adding this relationship() to the <class 'models.User'> class after both dependent classes have been defined.
2024-10-13 20:25:02,037 - auth - DEBUG - After request, Origin: http://localhost:3000
2024-10-13 20:25:02,037 - werkzeug - INFO - 127.0.0.1 - - [13/Oct/2024 20:25:02] "[35m[1mGET /api/sessions/165 HTTP/1.1[0m" 500 -
2024-10-13 20:25:04,673 - minutememo_app.app - ERROR - Exception on /api/subscription-status [GET]
Traceback (most recent call last):
  File "/Users/gaetanbuelinckx/minutememo_app/venv/lib/python3.12/site-packages/flask/app.py", line 1473, in wsgi_app
    response = self.full_dispatch_request()
               ^^^^^^^^^^^^^^^^^^^^^^^^^^^^
  File "/Users/gaetanbuelinckx/minutememo_app/venv/lib/python3.12/site-packages/flask/app.py", line 882, in full_dispatch_request
    rv = self.handle_user_exception(e)
         ^^^^^^^^^^^^^^^^^^^^^^^^^^^^^
  File "/Users/gaetanbuelinckx/minutememo_app/venv/lib/python3.12/site-packages/flask_cors/extension.py", line 178, in wrapped_function
    return cors_after_request(app.make_response(f(*args, **kwargs)))
                                                ^^^^^^^^^^^^^^^^^^
  File "/Users/gaetanbuelinckx/minutememo_app/venv/lib/python3.12/site-packages/flask/app.py", line 880, in full_dispatch_request
    rv = self.dispatch_request()
         ^^^^^^^^^^^^^^^^^^^^^^^
  File "/Users/gaetanbuelinckx/minutememo_app/venv/lib/python3.12/site-packages/flask/app.py", line 865, in dispatch_request
    return self.ensure_sync(self.view_functions[rule.endpoint])(**view_args)  # type: ignore[no-any-return]
           ^^^^^^^^^^^^^^^^^^^^^^^^^^^^^^^^^^^^^^^^^^^^^^^^^^^^^^^^^^^^^^^^^
  File "/Users/gaetanbuelinckx/minutememo_app/venv/lib/python3.12/site-packages/flask_login/utils.py", line 284, in decorated_view
    elif not current_user.is_authenticated:
             ^^^^^^^^^^^^^^^^^^^^^^^^^^^^^
  File "/Users/gaetanbuelinckx/minutememo_app/venv/lib/python3.12/site-packages/werkzeug/local.py", line 318, in __get__
    obj = instance._get_current_object()
          ^^^^^^^^^^^^^^^^^^^^^^^^^^^^^^
  File "/Users/gaetanbuelinckx/minutememo_app/venv/lib/python3.12/site-packages/werkzeug/local.py", line 526, in _get_current_object
    return get_name(local())
                    ^^^^^^^
  File "/Users/gaetanbuelinckx/minutememo_app/venv/lib/python3.12/site-packages/flask_login/utils.py", line 25, in <lambda>
    current_user = LocalProxy(lambda: _get_user())
                                      ^^^^^^^^^^^
  File "/Users/gaetanbuelinckx/minutememo_app/venv/lib/python3.12/site-packages/flask_login/utils.py", line 370, in _get_user
    current_app.login_manager._load_user()
  File "/Users/gaetanbuelinckx/minutememo_app/venv/lib/python3.12/site-packages/flask_login/login_manager.py", line 364, in _load_user
    user = self._user_callback(user_id)
           ^^^^^^^^^^^^^^^^^^^^^^^^^^^^
  File "/Users/gaetanbuelinckx/minutememo_app/app.py", line 108, in load_user
    return User.query.get(int(user_id))
           ^^^^^^^^^^
  File "/Users/gaetanbuelinckx/minutememo_app/venv/lib/python3.12/site-packages/flask_sqlalchemy/model.py", line 22, in __get__
    return cls.query_class(
           ^^^^^^^^^^^^^^^^
  File "/Users/gaetanbuelinckx/minutememo_app/venv/lib/python3.12/site-packages/sqlalchemy/orm/query.py", line 275, in __init__
    self._set_entities(entities)
  File "/Users/gaetanbuelinckx/minutememo_app/venv/lib/python3.12/site-packages/sqlalchemy/orm/query.py", line 288, in _set_entities
    coercions.expect(
  File "/Users/gaetanbuelinckx/minutememo_app/venv/lib/python3.12/site-packages/sqlalchemy/sql/coercions.py", line 389, in expect
    insp._post_inspect
  File "/Users/gaetanbuelinckx/minutememo_app/venv/lib/python3.12/site-packages/sqlalchemy/util/langhelpers.py", line 1253, in __get__
    obj.__dict__[self.__name__] = result = self.fget(obj)
                                           ^^^^^^^^^^^^^^
  File "/Users/gaetanbuelinckx/minutememo_app/venv/lib/python3.12/site-packages/sqlalchemy/orm/mapper.py", line 2711, in _post_inspect
    self._check_configure()
  File "/Users/gaetanbuelinckx/minutememo_app/venv/lib/python3.12/site-packages/sqlalchemy/orm/mapper.py", line 2388, in _check_configure
    _configure_registries({self.registry}, cascade=True)
  File "/Users/gaetanbuelinckx/minutememo_app/venv/lib/python3.12/site-packages/sqlalchemy/orm/mapper.py", line 4204, in _configure_registries
    _do_configure_registries(registries, cascade)
  File "/Users/gaetanbuelinckx/minutememo_app/venv/lib/python3.12/site-packages/sqlalchemy/orm/mapper.py", line 4241, in _do_configure_registries
    raise e
sqlalchemy.exc.InvalidRequestError: One or more mappers failed to initialize - can't proceed with initialization of other mappers. Triggering mapper: 'Mapper[User(user)]'. Original exception was: When initializing mapper Mapper[User(user)], expression 'meeting_participants' failed to locate a name ("name 'meeting_participants' is not defined"). If this is a class name, consider adding this relationship() to the <class 'models.User'> class after both dependent classes have been defined.
2024-10-13 20:25:04,674 - auth - DEBUG - After request, Origin: http://localhost:3000
2024-10-13 20:25:04,675 - werkzeug - INFO - 127.0.0.1 - - [13/Oct/2024 20:25:04] "[35m[1mGET /api/subscription-status HTTP/1.1[0m" 500 -
2024-10-13 20:25:04,677 - minutememo_app.app - ERROR - Exception on /api/subscription-status [GET]
Traceback (most recent call last):
  File "/Users/gaetanbuelinckx/minutememo_app/venv/lib/python3.12/site-packages/flask/app.py", line 1473, in wsgi_app
    response = self.full_dispatch_request()
               ^^^^^^^^^^^^^^^^^^^^^^^^^^^^
  File "/Users/gaetanbuelinckx/minutememo_app/venv/lib/python3.12/site-packages/flask/app.py", line 882, in full_dispatch_request
    rv = self.handle_user_exception(e)
         ^^^^^^^^^^^^^^^^^^^^^^^^^^^^^
  File "/Users/gaetanbuelinckx/minutememo_app/venv/lib/python3.12/site-packages/flask_cors/extension.py", line 178, in wrapped_function
    return cors_after_request(app.make_response(f(*args, **kwargs)))
                                                ^^^^^^^^^^^^^^^^^^
  File "/Users/gaetanbuelinckx/minutememo_app/venv/lib/python3.12/site-packages/flask/app.py", line 880, in full_dispatch_request
    rv = self.dispatch_request()
         ^^^^^^^^^^^^^^^^^^^^^^^
  File "/Users/gaetanbuelinckx/minutememo_app/venv/lib/python3.12/site-packages/flask/app.py", line 865, in dispatch_request
    return self.ensure_sync(self.view_functions[rule.endpoint])(**view_args)  # type: ignore[no-any-return]
           ^^^^^^^^^^^^^^^^^^^^^^^^^^^^^^^^^^^^^^^^^^^^^^^^^^^^^^^^^^^^^^^^^
  File "/Users/gaetanbuelinckx/minutememo_app/venv/lib/python3.12/site-packages/flask_login/utils.py", line 284, in decorated_view
    elif not current_user.is_authenticated:
             ^^^^^^^^^^^^^^^^^^^^^^^^^^^^^
  File "/Users/gaetanbuelinckx/minutememo_app/venv/lib/python3.12/site-packages/werkzeug/local.py", line 318, in __get__
    obj = instance._get_current_object()
          ^^^^^^^^^^^^^^^^^^^^^^^^^^^^^^
  File "/Users/gaetanbuelinckx/minutememo_app/venv/lib/python3.12/site-packages/werkzeug/local.py", line 526, in _get_current_object
    return get_name(local())
                    ^^^^^^^
  File "/Users/gaetanbuelinckx/minutememo_app/venv/lib/python3.12/site-packages/flask_login/utils.py", line 25, in <lambda>
    current_user = LocalProxy(lambda: _get_user())
                                      ^^^^^^^^^^^
  File "/Users/gaetanbuelinckx/minutememo_app/venv/lib/python3.12/site-packages/flask_login/utils.py", line 370, in _get_user
    current_app.login_manager._load_user()
  File "/Users/gaetanbuelinckx/minutememo_app/venv/lib/python3.12/site-packages/flask_login/login_manager.py", line 364, in _load_user
    user = self._user_callback(user_id)
           ^^^^^^^^^^^^^^^^^^^^^^^^^^^^
  File "/Users/gaetanbuelinckx/minutememo_app/app.py", line 108, in load_user
    return User.query.get(int(user_id))
           ^^^^^^^^^^
  File "/Users/gaetanbuelinckx/minutememo_app/venv/lib/python3.12/site-packages/flask_sqlalchemy/model.py", line 22, in __get__
    return cls.query_class(
           ^^^^^^^^^^^^^^^^
  File "/Users/gaetanbuelinckx/minutememo_app/venv/lib/python3.12/site-packages/sqlalchemy/orm/query.py", line 275, in __init__
    self._set_entities(entities)
  File "/Users/gaetanbuelinckx/minutememo_app/venv/lib/python3.12/site-packages/sqlalchemy/orm/query.py", line 288, in _set_entities
    coercions.expect(
  File "/Users/gaetanbuelinckx/minutememo_app/venv/lib/python3.12/site-packages/sqlalchemy/sql/coercions.py", line 389, in expect
    insp._post_inspect
  File "/Users/gaetanbuelinckx/minutememo_app/venv/lib/python3.12/site-packages/sqlalchemy/util/langhelpers.py", line 1253, in __get__
    obj.__dict__[self.__name__] = result = self.fget(obj)
                                           ^^^^^^^^^^^^^^
  File "/Users/gaetanbuelinckx/minutememo_app/venv/lib/python3.12/site-packages/sqlalchemy/orm/mapper.py", line 2711, in _post_inspect
    self._check_configure()
  File "/Users/gaetanbuelinckx/minutememo_app/venv/lib/python3.12/site-packages/sqlalchemy/orm/mapper.py", line 2388, in _check_configure
    _configure_registries({self.registry}, cascade=True)
  File "/Users/gaetanbuelinckx/minutememo_app/venv/lib/python3.12/site-packages/sqlalchemy/orm/mapper.py", line 4204, in _configure_registries
    _do_configure_registries(registries, cascade)
  File "/Users/gaetanbuelinckx/minutememo_app/venv/lib/python3.12/site-packages/sqlalchemy/orm/mapper.py", line 4241, in _do_configure_registries
    raise e
sqlalchemy.exc.InvalidRequestError: One or more mappers failed to initialize - can't proceed with initialization of other mappers. Triggering mapper: 'Mapper[User(user)]'. Original exception was: When initializing mapper Mapper[User(user)], expression 'meeting_participants' failed to locate a name ("name 'meeting_participants' is not defined"). If this is a class name, consider adding this relationship() to the <class 'models.User'> class after both dependent classes have been defined.
2024-10-13 20:25:04,679 - auth - DEBUG - After request, Origin: http://localhost:3000
2024-10-13 20:25:04,679 - werkzeug - INFO - 127.0.0.1 - - [13/Oct/2024 20:25:04] "[35m[1mGET /api/subscription-status HTTP/1.1[0m" 500 -
2024-10-13 20:25:07,220 - minutememo_app.app - ERROR - Exception on /auth/logout [GET]
Traceback (most recent call last):
  File "/Users/gaetanbuelinckx/minutememo_app/venv/lib/python3.12/site-packages/flask/app.py", line 1473, in wsgi_app
    response = self.full_dispatch_request()
               ^^^^^^^^^^^^^^^^^^^^^^^^^^^^
  File "/Users/gaetanbuelinckx/minutememo_app/venv/lib/python3.12/site-packages/flask/app.py", line 882, in full_dispatch_request
    rv = self.handle_user_exception(e)
         ^^^^^^^^^^^^^^^^^^^^^^^^^^^^^
  File "/Users/gaetanbuelinckx/minutememo_app/venv/lib/python3.12/site-packages/flask_cors/extension.py", line 178, in wrapped_function
    return cors_after_request(app.make_response(f(*args, **kwargs)))
                                                ^^^^^^^^^^^^^^^^^^
  File "/Users/gaetanbuelinckx/minutememo_app/venv/lib/python3.12/site-packages/flask/app.py", line 880, in full_dispatch_request
    rv = self.dispatch_request()
         ^^^^^^^^^^^^^^^^^^^^^^^
  File "/Users/gaetanbuelinckx/minutememo_app/venv/lib/python3.12/site-packages/flask/app.py", line 865, in dispatch_request
    return self.ensure_sync(self.view_functions[rule.endpoint])(**view_args)  # type: ignore[no-any-return]
           ^^^^^^^^^^^^^^^^^^^^^^^^^^^^^^^^^^^^^^^^^^^^^^^^^^^^^^^^^^^^^^^^^
  File "/Users/gaetanbuelinckx/minutememo_app/venv/lib/python3.12/site-packages/flask_login/utils.py", line 284, in decorated_view
    elif not current_user.is_authenticated:
             ^^^^^^^^^^^^^^^^^^^^^^^^^^^^^
  File "/Users/gaetanbuelinckx/minutememo_app/venv/lib/python3.12/site-packages/werkzeug/local.py", line 318, in __get__
    obj = instance._get_current_object()
          ^^^^^^^^^^^^^^^^^^^^^^^^^^^^^^
  File "/Users/gaetanbuelinckx/minutememo_app/venv/lib/python3.12/site-packages/werkzeug/local.py", line 526, in _get_current_object
    return get_name(local())
                    ^^^^^^^
  File "/Users/gaetanbuelinckx/minutememo_app/venv/lib/python3.12/site-packages/flask_login/utils.py", line 25, in <lambda>
    current_user = LocalProxy(lambda: _get_user())
                                      ^^^^^^^^^^^
  File "/Users/gaetanbuelinckx/minutememo_app/venv/lib/python3.12/site-packages/flask_login/utils.py", line 370, in _get_user
    current_app.login_manager._load_user()
  File "/Users/gaetanbuelinckx/minutememo_app/venv/lib/python3.12/site-packages/flask_login/login_manager.py", line 364, in _load_user
    user = self._user_callback(user_id)
           ^^^^^^^^^^^^^^^^^^^^^^^^^^^^
  File "/Users/gaetanbuelinckx/minutememo_app/app.py", line 108, in load_user
    return User.query.get(int(user_id))
           ^^^^^^^^^^
  File "/Users/gaetanbuelinckx/minutememo_app/venv/lib/python3.12/site-packages/flask_sqlalchemy/model.py", line 22, in __get__
    return cls.query_class(
           ^^^^^^^^^^^^^^^^
  File "/Users/gaetanbuelinckx/minutememo_app/venv/lib/python3.12/site-packages/sqlalchemy/orm/query.py", line 275, in __init__
    self._set_entities(entities)
  File "/Users/gaetanbuelinckx/minutememo_app/venv/lib/python3.12/site-packages/sqlalchemy/orm/query.py", line 288, in _set_entities
    coercions.expect(
  File "/Users/gaetanbuelinckx/minutememo_app/venv/lib/python3.12/site-packages/sqlalchemy/sql/coercions.py", line 389, in expect
    insp._post_inspect
  File "/Users/gaetanbuelinckx/minutememo_app/venv/lib/python3.12/site-packages/sqlalchemy/util/langhelpers.py", line 1253, in __get__
    obj.__dict__[self.__name__] = result = self.fget(obj)
                                           ^^^^^^^^^^^^^^
  File "/Users/gaetanbuelinckx/minutememo_app/venv/lib/python3.12/site-packages/sqlalchemy/orm/mapper.py", line 2711, in _post_inspect
    self._check_configure()
  File "/Users/gaetanbuelinckx/minutememo_app/venv/lib/python3.12/site-packages/sqlalchemy/orm/mapper.py", line 2388, in _check_configure
    _configure_registries({self.registry}, cascade=True)
  File "/Users/gaetanbuelinckx/minutememo_app/venv/lib/python3.12/site-packages/sqlalchemy/orm/mapper.py", line 4204, in _configure_registries
    _do_configure_registries(registries, cascade)
  File "/Users/gaetanbuelinckx/minutememo_app/venv/lib/python3.12/site-packages/sqlalchemy/orm/mapper.py", line 4241, in _do_configure_registries
    raise e
sqlalchemy.exc.InvalidRequestError: One or more mappers failed to initialize - can't proceed with initialization of other mappers. Triggering mapper: 'Mapper[User(user)]'. Original exception was: When initializing mapper Mapper[User(user)], expression 'meeting_participants' failed to locate a name ("name 'meeting_participants' is not defined"). If this is a class name, consider adding this relationship() to the <class 'models.User'> class after both dependent classes have been defined.
2024-10-13 20:25:07,222 - auth - DEBUG - After request, Origin: http://localhost:3000
2024-10-13 20:25:07,223 - werkzeug - INFO - 127.0.0.1 - - [13/Oct/2024 20:25:07] "[35m[1mGET /auth/logout HTTP/1.1[0m" 500 -
2024-10-13 20:25:08,287 - auth - DEBUG - Google login initiated. Redirect URI: http://localhost:5000/auth/callback, State: 57oCwAe9kyKSYsG-x8MYKA
2024-10-13 20:25:08,287 - auth - DEBUG - Client ID: 760628373064-ccotsm9m4l9q81a9e6gmtfj9gjudjpt1.apps.googleusercontent.com
2024-10-13 20:25:08,287 - auth - DEBUG - Client Secret: REDACTED
2024-10-13 20:25:08,287 - auth - DEBUG - Session contents: <SecureCookieSession {'_flashes': [('message', 'Please log in to access this page.'), ('message', 'Please log in to access this page.'), ('message', 'Please log in to access this page.'), ('message', 'Please log in to access this page.'), ('message', 'Please log in to access this page.'), ('message', 'Please log in to access this page.'), ('message', 'Please log in to access this page.'), ('message', 'Please log in to access this page.'), ('message', 'Please log in to access this page.'), ('message', 'Please log in to access this page.'), ('message', 'Please log in to access this page.'), ('message', 'Please log in to access this page.'), ('message', 'Please log in to access this page.'), ('message', 'Please log in to access this page.'), ('message', 'Please log in to access this page.')], '_fresh': True, '_id': '80f0c8f52e9d0894341645dd90e6d8ae068eccca8a01568dae0e1571fcf8617cd62df66b248fa262c3936ab84cb81e2f75bd1e859e1c93555c3e41b7cf1c1e14', '_permanent': True, '_user_id': '14', 'oauth_state': '57oCwAe9kyKSYsG-x8MYKA'}>
2024-10-13 20:25:08,288 - auth - DEBUG - After request, Origin: None
2024-10-13 20:25:08,289 - werkzeug - INFO - 127.0.0.1 - - [13/Oct/2024 20:25:08] "[32mGET /auth/login/google HTTP/1.1[0m" 302 -
2024-10-13 20:25:16,394 - auth - DEBUG - Google authorization callback reached
2024-10-13 20:25:16,395 - auth - DEBUG - OAuth state: 57oCwAe9kyKSYsG-x8MYKA
2024-10-13 20:25:16,395 - auth - DEBUG - OAuth state data from session: {'data': {'nonce': '7P1uABk2t0pku4PNv1Am', 'redirect_uri': 'http://localhost:5000/auth/callback', 'url': 'https://accounts.google.com/o/oauth2/auth?response_type=code&client_id=760628373064-ccotsm9m4l9q81a9e6gmtfj9gjudjpt1.apps.googleusercontent.com&redirect_uri=http%3A%2F%2Flocalhost%3A5000%2Fauth%2Fcallback&scope=openid+email+profile+https%3A%2F%2Fwww.googleapis.com%2Fauth%2Fcalendar&state=57oCwAe9kyKSYsG-x8MYKA&access_type=offline&prompt=consent&nonce=7P1uABk2t0pku4PNv1Am'}, 'exp': 1728847508.288468}
2024-10-13 20:25:16,395 - auth - DEBUG - Nonce retrieved: 7P1uABk2t0pku4PNv1Am
2024-10-13 20:25:16,402 - urllib3.connectionpool - DEBUG - Starting new HTTPS connection (1): accounts.google.com:443
2024-10-13 20:25:16,553 - urllib3.connectionpool - DEBUG - https://accounts.google.com:443 "POST /o/oauth2/token HTTP/11" 200 None
2024-10-13 20:25:16,557 - urllib3.connectionpool - DEBUG - Starting new HTTPS connection (1): www.googleapis.com:443
2024-10-13 20:25:16,694 - urllib3.connectionpool - DEBUG - https://www.googleapis.com:443 "GET /oauth2/v3/certs HTTP/11" 200 745
2024-10-13 20:25:16,698 - auth - DEBUG - Token response received: {'access_token': 'ya29.a0AcM612ziEI2vZ9vAUIcGHuy4kRvWOUOkwq2PxslsWCfmMaIFRcPZOfJ1VLa0o2V14vuf60crElQiNfL0Zr3UlIgm17A7XO4Kmgs2sQZ-D9FryiMnYYPWyhab_sHrhw6ydWaLEueq6EWpB2lTGNs-8aT8V7_MQz87BKc4YrkoaCgYKATcSARASFQHGX2Mi5GMv9ItSe3CC3S3_Pwf-QQ0175', 'expires_in': 3599, 'refresh_token': '1//03dfcLycc17oeCgYIARAAGAMSNwF-L9IrKz4Q2o9Wjgk-CzxbfG0RULHRjpuG97Ej2XLf4O69lYQuaP4ZQCWMeU67zzlsJxJwLcM', 'scope': 'https://www.googleapis.com/auth/userinfo.email https://www.googleapis.com/auth/userinfo.profile openid https://www.googleapis.com/auth/calendar', 'token_type': 'Bearer', 'id_token': 'eyJhbGciOiJSUzI1NiIsImtpZCI6ImE1MGY2ZTcwZWY0YjU0OGE1ZmQ5MTQyZWVjZDFmYjhmNTRkY2U5ZWUiLCJ0eXAiOiJKV1QifQ.eyJpc3MiOiJhY2NvdW50cy5nb29nbGUuY29tIiwiYXpwIjoiNzYwNjI4MzczMDY0LWNjb3RzbTltNGw5cTgxYTllNmdtdGZqOWdqdWRqcHQxLmFwcHMuZ29vZ2xldXNlcmNvbnRlbnQuY29tIiwiYXVkIjoiNzYwNjI4MzczMDY0LWNjb3RzbTltNGw5cTgxYTllNmdtdGZqOWdqdWRqcHQxLmFwcHMuZ29vZ2xldXNlcmNvbnRlbnQuY29tIiwic3ViIjoiMTEzNDY1NzQxODQxMjQ0MzI5ODgwIiwiZW1haWwiOiJnYWV0YW4uYnVlbGluY2t4QGdtYWlsLmNvbSIsImVtYWlsX3ZlcmlmaWVkIjp0cnVlLCJhdF9oYXNoIjoiVFdtNVRzNHpZWEplQXFUV1kzYWYwZyIsIm5vbmNlIjoiN1AxdUFCazJ0MHBrdTRQTnYxQW0iLCJpYXQiOjE3Mjg4NDM5MTYsImV4cCI6MTcyODg0NzUxNn0.xOauwNWD9bnF2X3v5oK07k_IquyLQjpAmkYbmUQ5mp1SAAZHkLwODTkraYU8JFo22T4xKxnN40RgBaRglbeeQUZJQLKNDmE1SmMPDVB3a_Ll3mX1wlmdPLnpd0uvSHE2WbTzPcA72W5fUbl-XJmWGEp-_ejmqoPEnnG--Dus3W2XYU4NUh4rABzaNxCkMoJzu5uBSDhLeNW4y7xNd2BDh_1yIseaCpbqK4q4lgH3Uj77rNp7JRsdLfvjaBsOfIVTeVxdkXHAdAGtcMdGZVfcfpCXpDNmjsImMtzNh42_Sswf31Jcpah9MfJSsIzt_nHrRu8kGfA9VCRSHJgL8i3eeQ', 'expires_at': 1728847515, 'userinfo': {'iss': 'accounts.google.com', 'azp': '760628373064-ccotsm9m4l9q81a9e6gmtfj9gjudjpt1.apps.googleusercontent.com', 'aud': '760628373064-ccotsm9m4l9q81a9e6gmtfj9gjudjpt1.apps.googleusercontent.com', 'sub': '113465741841244329880', 'email': 'gaetan.buelinckx@gmail.com', 'email_verified': True, 'at_hash': 'TWm5Ts4zYXJeAqTWY3af0g', 'nonce': '7P1uABk2t0pku4PNv1Am', 'iat': 1728843916, 'exp': 1728847516}}
2024-10-13 20:25:16,699 - auth - DEBUG - User info: {'iss': 'accounts.google.com', 'azp': '760628373064-ccotsm9m4l9q81a9e6gmtfj9gjudjpt1.apps.googleusercontent.com', 'aud': '760628373064-ccotsm9m4l9q81a9e6gmtfj9gjudjpt1.apps.googleusercontent.com', 'sub': '113465741841244329880', 'email': 'gaetan.buelinckx@gmail.com', 'email_verified': True, 'at_hash': 'TWm5Ts4zYXJeAqTWY3af0g', 'nonce': '7P1uABk2t0pku4PNv1Am', 'iat': 1728843916, 'exp': 1728847516}
2024-10-13 20:25:16,699 - auth - DEBUG - User email: gaetan.buelinckx@gmail.com
2024-10-13 20:25:16,699 - auth - ERROR - Error during Google authorization: One or more mappers failed to initialize - can't proceed with initialization of other mappers. Triggering mapper: 'Mapper[User(user)]'. Original exception was: When initializing mapper Mapper[User(user)], expression 'meeting_participants' failed to locate a name ("name 'meeting_participants' is not defined"). If this is a class name, consider adding this relationship() to the <class 'models.User'> class after both dependent classes have been defined.
2024-10-13 20:25:16,699 - auth - DEBUG - After request, Origin: None
2024-10-13 20:25:16,699 - werkzeug - INFO - 127.0.0.1 - - [13/Oct/2024 20:25:16] "[35m[1mGET /auth/callback?state=57oCwAe9kyKSYsG-x8MYKA&code=4/0AVG7fiSqdSv9FKe1VnS_Eb6vKLDhNPt9NErmb1liuFq2sP6xu5NPPc3wt94SI1USJFp6vQ&scope=email%20profile%20openid%20https://www.googleapis.com/auth/calendar%20https://www.googleapis.com/auth/userinfo.profile%20https://www.googleapis.com/auth/userinfo.email&authuser=1&prompt=consent HTTP/1.1[0m" 500 -
2024-10-13 20:25:16,752 - auth - DEBUG - After request, Origin: None
2024-10-13 20:25:16,753 - werkzeug - INFO - 127.0.0.1 - - [13/Oct/2024 20:25:16] "[33mGET /favicon.ico HTTP/1.1[0m" 404 -
2024-10-13 20:26:53 DEBUG: This service is instrumented using OpenTelemetry. OpenTelemetry or one of its components could not be imported; please add compatible versions of opentelemetry-api and opentelemetry-instrumentation packages in order to get Storage Tracing data.
2024-10-13 20:26:53,410 - google.cloud.storage._opentelemetry_tracing - DEBUG - This service is instrumented using OpenTelemetry. OpenTelemetry or one of its components could not be imported; please add compatible versions of opentelemetry-api and opentelemetry-instrumentation packages in order to get Storage Tracing data.
2024-10-13 20:26:53 INFO: [31m[1mWARNING: This is a development server. Do not use it in a production deployment. Use a production WSGI server instead.[0m
 * Running on http://127.0.0.1:5000
2024-10-13 20:26:53,691 - werkzeug - INFO - [31m[1mWARNING: This is a development server. Do not use it in a production deployment. Use a production WSGI server instead.[0m
 * Running on http://127.0.0.1:5000
2024-10-13 20:26:53 INFO: [33mPress CTRL+C to quit[0m
2024-10-13 20:26:53,691 - werkzeug - INFO - [33mPress CTRL+C to quit[0m
2024-10-13 20:27:00 DEBUG: Google authorization callback reached
2024-10-13 20:27:00,416 - auth - DEBUG - Google authorization callback reached
2024-10-13 20:27:00 DEBUG: OAuth state: 57oCwAe9kyKSYsG-x8MYKA
2024-10-13 20:27:00,416 - auth - DEBUG - OAuth state: 57oCwAe9kyKSYsG-x8MYKA
2024-10-13 20:27:00 DEBUG: OAuth state data from session: None
2024-10-13 20:27:00,416 - auth - DEBUG - OAuth state data from session: None
2024-10-13 20:27:00 ERROR: Error during Google authorization: Missing nonce in session state data
2024-10-13 20:27:00,417 - auth - ERROR - Error during Google authorization: Missing nonce in session state data
2024-10-13 20:27:00 DEBUG: After request, Origin: None
2024-10-13 20:27:00,417 - auth - DEBUG - After request, Origin: None
2024-10-13 20:27:00 INFO: 127.0.0.1 - - [13/Oct/2024 20:27:00] "[35m[1mGET /auth/callback?state=57oCwAe9kyKSYsG-x8MYKA&code=4/0AVG7fiRfiq9jLZFz73lX50z9o58_dX50LAxbhBoXHym57LVDAK_ps0wFWPL_FxnkWwEdKg&scope=email%20profile%20openid%20https://www.googleapis.com/auth/calendar%20https://www.googleapis.com/auth/userinfo.profile%20https://www.googleapis.com/auth/userinfo.email&authuser=1&prompt=consent HTTP/1.1[0m" 500 -
2024-10-13 20:27:00,418 - werkzeug - INFO - 127.0.0.1 - - [13/Oct/2024 20:27:00] "[35m[1mGET /auth/callback?state=57oCwAe9kyKSYsG-x8MYKA&code=4/0AVG7fiRfiq9jLZFz73lX50z9o58_dX50LAxbhBoXHym57LVDAK_ps0wFWPL_FxnkWwEdKg&scope=email%20profile%20openid%20https://www.googleapis.com/auth/calendar%20https://www.googleapis.com/auth/userinfo.profile%20https://www.googleapis.com/auth/userinfo.email&authuser=1&prompt=consent HTTP/1.1[0m" 500 -
2024-10-13 20:30:38 DEBUG: This service is instrumented using OpenTelemetry. OpenTelemetry or one of its components could not be imported; please add compatible versions of opentelemetry-api and opentelemetry-instrumentation packages in order to get Storage Tracing data.
2024-10-13 20:30:38,031 - google.cloud.storage._opentelemetry_tracing - DEBUG - This service is instrumented using OpenTelemetry. OpenTelemetry or one of its components could not be imported; please add compatible versions of opentelemetry-api and opentelemetry-instrumentation packages in order to get Storage Tracing data.
2024-10-13 20:30:38 INFO: [31m[1mWARNING: This is a development server. Do not use it in a production deployment. Use a production WSGI server instead.[0m
 * Running on http://127.0.0.1:5000
2024-10-13 20:30:38,317 - werkzeug - INFO - [31m[1mWARNING: This is a development server. Do not use it in a production deployment. Use a production WSGI server instead.[0m
 * Running on http://127.0.0.1:5000
2024-10-13 20:30:38 INFO: [33mPress CTRL+C to quit[0m
2024-10-13 20:30:38,317 - werkzeug - INFO - [33mPress CTRL+C to quit[0m
2024-10-13 20:30:49 DEBUG: Google authorization callback reached
2024-10-13 20:30:49,749 - auth - DEBUG - Google authorization callback reached
2024-10-13 20:30:49 DEBUG: OAuth state: 57oCwAe9kyKSYsG-x8MYKA
2024-10-13 20:30:49,749 - auth - DEBUG - OAuth state: 57oCwAe9kyKSYsG-x8MYKA
2024-10-13 20:30:49 ERROR: Error during Google authorization: mismatching_state: CSRF Warning! State not equal in request and response.
2024-10-13 20:30:49,750 - auth - ERROR - Error during Google authorization: mismatching_state: CSRF Warning! State not equal in request and response.
2024-10-13 20:30:49 DEBUG: After request, Origin: None
2024-10-13 20:30:49,750 - auth - DEBUG - After request, Origin: None
2024-10-13 20:30:49 INFO: 127.0.0.1 - - [13/Oct/2024 20:30:49] "[35m[1mGET /auth/callback?state=57oCwAe9kyKSYsG-x8MYKA&code=4/0AVG7fiQ9Ya6khILB27RRAQfHm5rntDMJb1gpBPQPoOnVcxxZjfBIy5Xh4WvqM6DaMFlSZg&scope=email%20profile%20openid%20https://www.googleapis.com/auth/calendar%20https://www.googleapis.com/auth/userinfo.profile%20https://www.googleapis.com/auth/userinfo.email&authuser=1&prompt=consent HTTP/1.1[0m" 500 -
2024-10-13 20:30:49,750 - werkzeug - INFO - 127.0.0.1 - - [13/Oct/2024 20:30:49] "[35m[1mGET /auth/callback?state=57oCwAe9kyKSYsG-x8MYKA&code=4/0AVG7fiQ9Ya6khILB27RRAQfHm5rntDMJb1gpBPQPoOnVcxxZjfBIy5Xh4WvqM6DaMFlSZg&scope=email%20profile%20openid%20https://www.googleapis.com/auth/calendar%20https://www.googleapis.com/auth/userinfo.profile%20https://www.googleapis.com/auth/userinfo.email&authuser=1&prompt=consent HTTP/1.1[0m" 500 -
2024-10-13 20:31:49 DEBUG: After request, Origin: https://minutememo-jclyfg21m-gaetan-buelinckxs-projects.vercel.app
2024-10-13 20:31:49,708 - auth - DEBUG - After request, Origin: https://minutememo-jclyfg21m-gaetan-buelinckxs-projects.vercel.app
2024-10-13 20:31:49 INFO: 127.0.0.1 - - [13/Oct/2024 20:31:49] "OPTIONS / HTTP/1.1" 200 -
2024-10-13 20:31:49,708 - werkzeug - INFO - 127.0.0.1 - - [13/Oct/2024 20:31:49] "OPTIONS / HTTP/1.1" 200 -
2024-10-13 20:31:49 DEBUG: After request, Origin: https://minutememo-jclyfg21m-gaetan-buelinckxs-projects.vercel.app
2024-10-13 20:31:49,710 - auth - DEBUG - After request, Origin: https://minutememo-jclyfg21m-gaetan-buelinckxs-projects.vercel.app
2024-10-13 20:31:49 INFO: 127.0.0.1 - - [13/Oct/2024 20:31:49] "[32mGET / HTTP/1.1[0m" 302 -
2024-10-13 20:31:49,710 - werkzeug - INFO - 127.0.0.1 - - [13/Oct/2024 20:31:49] "[32mGET / HTTP/1.1[0m" 302 -
2024-10-13 20:31:49 DEBUG: After request, Origin: https://minutememo-jclyfg21m-gaetan-buelinckxs-projects.vercel.app
2024-10-13 20:31:49,714 - auth - DEBUG - After request, Origin: https://minutememo-jclyfg21m-gaetan-buelinckxs-projects.vercel.app
2024-10-13 20:31:49 INFO: 127.0.0.1 - - [13/Oct/2024 20:31:49] "OPTIONS /auth/login?next=/ HTTP/1.1" 200 -
2024-10-13 20:31:49,714 - werkzeug - INFO - 127.0.0.1 - - [13/Oct/2024 20:31:49] "OPTIONS /auth/login?next=/ HTTP/1.1" 200 -
2024-10-13 20:31:49 DEBUG: After request, Origin: https://minutememo-jclyfg21m-gaetan-buelinckxs-projects.vercel.app
2024-10-13 20:31:49,715 - auth - DEBUG - After request, Origin: https://minutememo-jclyfg21m-gaetan-buelinckxs-projects.vercel.app
2024-10-13 20:31:49 INFO: 127.0.0.1 - - [13/Oct/2024 20:31:49] "[31m[1mGET /auth/login?next=/ HTTP/1.1[0m" 405 -
2024-10-13 20:31:49,716 - werkzeug - INFO - 127.0.0.1 - - [13/Oct/2024 20:31:49] "[31m[1mGET /auth/login?next=/ HTTP/1.1[0m" 405 -
2024-10-13 20:31:53 ERROR: Exception on /auth/status [GET]
Traceback (most recent call last):
  File "/Users/gaetanbuelinckx/minutememo_app/venv/lib/python3.12/site-packages/sqlalchemy/orm/clsregistry.py", line 532, in __call__
    x = eval(self.arg, globals(), self._dict)
        ^^^^^^^^^^^^^^^^^^^^^^^^^^^^^^^^^^^^^
  File "<string>", line 1, in <module>
NameError: name 'meeting_participants' is not defined

The above exception was the direct cause of the following exception:

Traceback (most recent call last):
  File "/Users/gaetanbuelinckx/minutememo_app/venv/lib/python3.12/site-packages/flask/app.py", line 1473, in wsgi_app
    response = self.full_dispatch_request()
               ^^^^^^^^^^^^^^^^^^^^^^^^^^^^
  File "/Users/gaetanbuelinckx/minutememo_app/venv/lib/python3.12/site-packages/flask/app.py", line 882, in full_dispatch_request
    rv = self.handle_user_exception(e)
         ^^^^^^^^^^^^^^^^^^^^^^^^^^^^^
  File "/Users/gaetanbuelinckx/minutememo_app/venv/lib/python3.12/site-packages/flask_cors/extension.py", line 178, in wrapped_function
    return cors_after_request(app.make_response(f(*args, **kwargs)))
                                                ^^^^^^^^^^^^^^^^^^
  File "/Users/gaetanbuelinckx/minutememo_app/venv/lib/python3.12/site-packages/flask/app.py", line 880, in full_dispatch_request
    rv = self.dispatch_request()
         ^^^^^^^^^^^^^^^^^^^^^^^
  File "/Users/gaetanbuelinckx/minutememo_app/venv/lib/python3.12/site-packages/flask/app.py", line 865, in dispatch_request
    return self.ensure_sync(self.view_functions[rule.endpoint])(**view_args)  # type: ignore[no-any-return]
           ^^^^^^^^^^^^^^^^^^^^^^^^^^^^^^^^^^^^^^^^^^^^^^^^^^^^^^^^^^^^^^^^^
  File "/Users/gaetanbuelinckx/minutememo_app/app.py", line 118, in status
    if current_user.is_authenticated:
       ^^^^^^^^^^^^^^^^^^^^^^^^^^^^^
  File "/Users/gaetanbuelinckx/minutememo_app/venv/lib/python3.12/site-packages/werkzeug/local.py", line 318, in __get__
    obj = instance._get_current_object()
          ^^^^^^^^^^^^^^^^^^^^^^^^^^^^^^
  File "/Users/gaetanbuelinckx/minutememo_app/venv/lib/python3.12/site-packages/werkzeug/local.py", line 526, in _get_current_object
    return get_name(local())
                    ^^^^^^^
  File "/Users/gaetanbuelinckx/minutememo_app/venv/lib/python3.12/site-packages/flask_login/utils.py", line 25, in <lambda>
    current_user = LocalProxy(lambda: _get_user())
                                      ^^^^^^^^^^^
  File "/Users/gaetanbuelinckx/minutememo_app/venv/lib/python3.12/site-packages/flask_login/utils.py", line 370, in _get_user
    current_app.login_manager._load_user()
  File "/Users/gaetanbuelinckx/minutememo_app/venv/lib/python3.12/site-packages/flask_login/login_manager.py", line 364, in _load_user
    user = self._user_callback(user_id)
           ^^^^^^^^^^^^^^^^^^^^^^^^^^^^
  File "/Users/gaetanbuelinckx/minutememo_app/app.py", line 108, in load_user
    return User.query.get(int(user_id))
           ^^^^^^^^^^
  File "/Users/gaetanbuelinckx/minutememo_app/venv/lib/python3.12/site-packages/flask_sqlalchemy/model.py", line 22, in __get__
    return cls.query_class(
           ^^^^^^^^^^^^^^^^
  File "/Users/gaetanbuelinckx/minutememo_app/venv/lib/python3.12/site-packages/sqlalchemy/orm/query.py", line 275, in __init__
    self._set_entities(entities)
  File "/Users/gaetanbuelinckx/minutememo_app/venv/lib/python3.12/site-packages/sqlalchemy/orm/query.py", line 288, in _set_entities
    coercions.expect(
  File "/Users/gaetanbuelinckx/minutememo_app/venv/lib/python3.12/site-packages/sqlalchemy/sql/coercions.py", line 389, in expect
    insp._post_inspect
  File "/Users/gaetanbuelinckx/minutememo_app/venv/lib/python3.12/site-packages/sqlalchemy/util/langhelpers.py", line 1253, in __get__
    obj.__dict__[self.__name__] = result = self.fget(obj)
                                           ^^^^^^^^^^^^^^
  File "/Users/gaetanbuelinckx/minutememo_app/venv/lib/python3.12/site-packages/sqlalchemy/orm/mapper.py", line 2711, in _post_inspect
    self._check_configure()
  File "/Users/gaetanbuelinckx/minutememo_app/venv/lib/python3.12/site-packages/sqlalchemy/orm/mapper.py", line 2388, in _check_configure
    _configure_registries({self.registry}, cascade=True)
  File "/Users/gaetanbuelinckx/minutememo_app/venv/lib/python3.12/site-packages/sqlalchemy/orm/mapper.py", line 4204, in _configure_registries
    _do_configure_registries(registries, cascade)
  File "/Users/gaetanbuelinckx/minutememo_app/venv/lib/python3.12/site-packages/sqlalchemy/orm/mapper.py", line 4245, in _do_configure_registries
    mapper._post_configure_properties()
  File "/Users/gaetanbuelinckx/minutememo_app/venv/lib/python3.12/site-packages/sqlalchemy/orm/mapper.py", line 2405, in _post_configure_properties
    prop.init()
  File "/Users/gaetanbuelinckx/minutememo_app/venv/lib/python3.12/site-packages/sqlalchemy/orm/interfaces.py", line 584, in init
    self.do_init()
  File "/Users/gaetanbuelinckx/minutememo_app/venv/lib/python3.12/site-packages/sqlalchemy/orm/relationships.py", line 1641, in do_init
    self._process_dependent_arguments()
  File "/Users/gaetanbuelinckx/minutememo_app/venv/lib/python3.12/site-packages/sqlalchemy/orm/relationships.py", line 1682, in _process_dependent_arguments
    rel_arg._resolve_against_registry(self._clsregistry_resolvers[1])
  File "/Users/gaetanbuelinckx/minutememo_app/venv/lib/python3.12/site-packages/sqlalchemy/orm/relationships.py", line 270, in _resolve_against_registry
    self.resolved = clsregistry_resolver(
                    ^^^^^^^^^^^^^^^^^^^^^
  File "/Users/gaetanbuelinckx/minutememo_app/venv/lib/python3.12/site-packages/sqlalchemy/orm/clsregistry.py", line 539, in __call__
    self._raise_for_name(n.args[0], n)
  File "/Users/gaetanbuelinckx/minutememo_app/venv/lib/python3.12/site-packages/sqlalchemy/orm/clsregistry.py", line 500, in _raise_for_name
    raise exc.InvalidRequestError(
sqlalchemy.exc.InvalidRequestError: When initializing mapper Mapper[User(user)], expression 'meeting_participants' failed to locate a name ("name 'meeting_participants' is not defined"). If this is a class name, consider adding this relationship() to the <class 'models.User'> class after both dependent classes have been defined.
2024-10-13 20:31:53,401 - minutememo_app.app - ERROR - Exception on /auth/status [GET]
Traceback (most recent call last):
  File "/Users/gaetanbuelinckx/minutememo_app/venv/lib/python3.12/site-packages/sqlalchemy/orm/clsregistry.py", line 532, in __call__
    x = eval(self.arg, globals(), self._dict)
        ^^^^^^^^^^^^^^^^^^^^^^^^^^^^^^^^^^^^^
  File "<string>", line 1, in <module>
NameError: name 'meeting_participants' is not defined

The above exception was the direct cause of the following exception:

Traceback (most recent call last):
  File "/Users/gaetanbuelinckx/minutememo_app/venv/lib/python3.12/site-packages/flask/app.py", line 1473, in wsgi_app
    response = self.full_dispatch_request()
               ^^^^^^^^^^^^^^^^^^^^^^^^^^^^
  File "/Users/gaetanbuelinckx/minutememo_app/venv/lib/python3.12/site-packages/flask/app.py", line 882, in full_dispatch_request
    rv = self.handle_user_exception(e)
         ^^^^^^^^^^^^^^^^^^^^^^^^^^^^^
  File "/Users/gaetanbuelinckx/minutememo_app/venv/lib/python3.12/site-packages/flask_cors/extension.py", line 178, in wrapped_function
    return cors_after_request(app.make_response(f(*args, **kwargs)))
                                                ^^^^^^^^^^^^^^^^^^
  File "/Users/gaetanbuelinckx/minutememo_app/venv/lib/python3.12/site-packages/flask/app.py", line 880, in full_dispatch_request
    rv = self.dispatch_request()
         ^^^^^^^^^^^^^^^^^^^^^^^
  File "/Users/gaetanbuelinckx/minutememo_app/venv/lib/python3.12/site-packages/flask/app.py", line 865, in dispatch_request
    return self.ensure_sync(self.view_functions[rule.endpoint])(**view_args)  # type: ignore[no-any-return]
           ^^^^^^^^^^^^^^^^^^^^^^^^^^^^^^^^^^^^^^^^^^^^^^^^^^^^^^^^^^^^^^^^^
  File "/Users/gaetanbuelinckx/minutememo_app/app.py", line 118, in status
    if current_user.is_authenticated:
       ^^^^^^^^^^^^^^^^^^^^^^^^^^^^^
  File "/Users/gaetanbuelinckx/minutememo_app/venv/lib/python3.12/site-packages/werkzeug/local.py", line 318, in __get__
    obj = instance._get_current_object()
          ^^^^^^^^^^^^^^^^^^^^^^^^^^^^^^
  File "/Users/gaetanbuelinckx/minutememo_app/venv/lib/python3.12/site-packages/werkzeug/local.py", line 526, in _get_current_object
    return get_name(local())
                    ^^^^^^^
  File "/Users/gaetanbuelinckx/minutememo_app/venv/lib/python3.12/site-packages/flask_login/utils.py", line 25, in <lambda>
    current_user = LocalProxy(lambda: _get_user())
                                      ^^^^^^^^^^^
  File "/Users/gaetanbuelinckx/minutememo_app/venv/lib/python3.12/site-packages/flask_login/utils.py", line 370, in _get_user
    current_app.login_manager._load_user()
  File "/Users/gaetanbuelinckx/minutememo_app/venv/lib/python3.12/site-packages/flask_login/login_manager.py", line 364, in _load_user
    user = self._user_callback(user_id)
           ^^^^^^^^^^^^^^^^^^^^^^^^^^^^
  File "/Users/gaetanbuelinckx/minutememo_app/app.py", line 108, in load_user
    return User.query.get(int(user_id))
           ^^^^^^^^^^
  File "/Users/gaetanbuelinckx/minutememo_app/venv/lib/python3.12/site-packages/flask_sqlalchemy/model.py", line 22, in __get__
    return cls.query_class(
           ^^^^^^^^^^^^^^^^
  File "/Users/gaetanbuelinckx/minutememo_app/venv/lib/python3.12/site-packages/sqlalchemy/orm/query.py", line 275, in __init__
    self._set_entities(entities)
  File "/Users/gaetanbuelinckx/minutememo_app/venv/lib/python3.12/site-packages/sqlalchemy/orm/query.py", line 288, in _set_entities
    coercions.expect(
  File "/Users/gaetanbuelinckx/minutememo_app/venv/lib/python3.12/site-packages/sqlalchemy/sql/coercions.py", line 389, in expect
    insp._post_inspect
  File "/Users/gaetanbuelinckx/minutememo_app/venv/lib/python3.12/site-packages/sqlalchemy/util/langhelpers.py", line 1253, in __get__
    obj.__dict__[self.__name__] = result = self.fget(obj)
                                           ^^^^^^^^^^^^^^
  File "/Users/gaetanbuelinckx/minutememo_app/venv/lib/python3.12/site-packages/sqlalchemy/orm/mapper.py", line 2711, in _post_inspect
    self._check_configure()
  File "/Users/gaetanbuelinckx/minutememo_app/venv/lib/python3.12/site-packages/sqlalchemy/orm/mapper.py", line 2388, in _check_configure
    _configure_registries({self.registry}, cascade=True)
  File "/Users/gaetanbuelinckx/minutememo_app/venv/lib/python3.12/site-packages/sqlalchemy/orm/mapper.py", line 4204, in _configure_registries
    _do_configure_registries(registries, cascade)
  File "/Users/gaetanbuelinckx/minutememo_app/venv/lib/python3.12/site-packages/sqlalchemy/orm/mapper.py", line 4245, in _do_configure_registries
    mapper._post_configure_properties()
  File "/Users/gaetanbuelinckx/minutememo_app/venv/lib/python3.12/site-packages/sqlalchemy/orm/mapper.py", line 2405, in _post_configure_properties
    prop.init()
  File "/Users/gaetanbuelinckx/minutememo_app/venv/lib/python3.12/site-packages/sqlalchemy/orm/interfaces.py", line 584, in init
    self.do_init()
  File "/Users/gaetanbuelinckx/minutememo_app/venv/lib/python3.12/site-packages/sqlalchemy/orm/relationships.py", line 1641, in do_init
    self._process_dependent_arguments()
  File "/Users/gaetanbuelinckx/minutememo_app/venv/lib/python3.12/site-packages/sqlalchemy/orm/relationships.py", line 1682, in _process_dependent_arguments
    rel_arg._resolve_against_registry(self._clsregistry_resolvers[1])
  File "/Users/gaetanbuelinckx/minutememo_app/venv/lib/python3.12/site-packages/sqlalchemy/orm/relationships.py", line 270, in _resolve_against_registry
    self.resolved = clsregistry_resolver(
                    ^^^^^^^^^^^^^^^^^^^^^
  File "/Users/gaetanbuelinckx/minutememo_app/venv/lib/python3.12/site-packages/sqlalchemy/orm/clsregistry.py", line 539, in __call__
    self._raise_for_name(n.args[0], n)
  File "/Users/gaetanbuelinckx/minutememo_app/venv/lib/python3.12/site-packages/sqlalchemy/orm/clsregistry.py", line 500, in _raise_for_name
    raise exc.InvalidRequestError(
sqlalchemy.exc.InvalidRequestError: When initializing mapper Mapper[User(user)], expression 'meeting_participants' failed to locate a name ("name 'meeting_participants' is not defined"). If this is a class name, consider adding this relationship() to the <class 'models.User'> class after both dependent classes have been defined.
2024-10-13 20:31:53 DEBUG: After request, Origin: http://localhost:3000
2024-10-13 20:31:53,411 - auth - DEBUG - After request, Origin: http://localhost:3000
2024-10-13 20:31:53 INFO: 127.0.0.1 - - [13/Oct/2024 20:31:53] "[35m[1mGET /auth/status HTTP/1.1[0m" 500 -
2024-10-13 20:31:53,412 - werkzeug - INFO - 127.0.0.1 - - [13/Oct/2024 20:31:53] "[35m[1mGET /auth/status HTTP/1.1[0m" 500 -
2024-10-13 20:31:53 ERROR: Exception on /auth/status [GET]
Traceback (most recent call last):
  File "/Users/gaetanbuelinckx/minutememo_app/venv/lib/python3.12/site-packages/flask/app.py", line 1473, in wsgi_app
    response = self.full_dispatch_request()
               ^^^^^^^^^^^^^^^^^^^^^^^^^^^^
  File "/Users/gaetanbuelinckx/minutememo_app/venv/lib/python3.12/site-packages/flask/app.py", line 882, in full_dispatch_request
    rv = self.handle_user_exception(e)
         ^^^^^^^^^^^^^^^^^^^^^^^^^^^^^
  File "/Users/gaetanbuelinckx/minutememo_app/venv/lib/python3.12/site-packages/flask_cors/extension.py", line 178, in wrapped_function
    return cors_after_request(app.make_response(f(*args, **kwargs)))
                                                ^^^^^^^^^^^^^^^^^^
  File "/Users/gaetanbuelinckx/minutememo_app/venv/lib/python3.12/site-packages/flask/app.py", line 880, in full_dispatch_request
    rv = self.dispatch_request()
         ^^^^^^^^^^^^^^^^^^^^^^^
  File "/Users/gaetanbuelinckx/minutememo_app/venv/lib/python3.12/site-packages/flask/app.py", line 865, in dispatch_request
    return self.ensure_sync(self.view_functions[rule.endpoint])(**view_args)  # type: ignore[no-any-return]
           ^^^^^^^^^^^^^^^^^^^^^^^^^^^^^^^^^^^^^^^^^^^^^^^^^^^^^^^^^^^^^^^^^
  File "/Users/gaetanbuelinckx/minutememo_app/app.py", line 118, in status
    if current_user.is_authenticated:
       ^^^^^^^^^^^^^^^^^^^^^^^^^^^^^
  File "/Users/gaetanbuelinckx/minutememo_app/venv/lib/python3.12/site-packages/werkzeug/local.py", line 318, in __get__
    obj = instance._get_current_object()
          ^^^^^^^^^^^^^^^^^^^^^^^^^^^^^^
  File "/Users/gaetanbuelinckx/minutememo_app/venv/lib/python3.12/site-packages/werkzeug/local.py", line 526, in _get_current_object
    return get_name(local())
                    ^^^^^^^
  File "/Users/gaetanbuelinckx/minutememo_app/venv/lib/python3.12/site-packages/flask_login/utils.py", line 25, in <lambda>
    current_user = LocalProxy(lambda: _get_user())
                                      ^^^^^^^^^^^
  File "/Users/gaetanbuelinckx/minutememo_app/venv/lib/python3.12/site-packages/flask_login/utils.py", line 370, in _get_user
    current_app.login_manager._load_user()
  File "/Users/gaetanbuelinckx/minutememo_app/venv/lib/python3.12/site-packages/flask_login/login_manager.py", line 364, in _load_user
    user = self._user_callback(user_id)
           ^^^^^^^^^^^^^^^^^^^^^^^^^^^^
  File "/Users/gaetanbuelinckx/minutememo_app/app.py", line 108, in load_user
    return User.query.get(int(user_id))
           ^^^^^^^^^^
  File "/Users/gaetanbuelinckx/minutememo_app/venv/lib/python3.12/site-packages/flask_sqlalchemy/model.py", line 22, in __get__
    return cls.query_class(
           ^^^^^^^^^^^^^^^^
  File "/Users/gaetanbuelinckx/minutememo_app/venv/lib/python3.12/site-packages/sqlalchemy/orm/query.py", line 275, in __init__
    self._set_entities(entities)
  File "/Users/gaetanbuelinckx/minutememo_app/venv/lib/python3.12/site-packages/sqlalchemy/orm/query.py", line 288, in _set_entities
    coercions.expect(
  File "/Users/gaetanbuelinckx/minutememo_app/venv/lib/python3.12/site-packages/sqlalchemy/sql/coercions.py", line 389, in expect
    insp._post_inspect
  File "/Users/gaetanbuelinckx/minutememo_app/venv/lib/python3.12/site-packages/sqlalchemy/util/langhelpers.py", line 1253, in __get__
    obj.__dict__[self.__name__] = result = self.fget(obj)
                                           ^^^^^^^^^^^^^^
  File "/Users/gaetanbuelinckx/minutememo_app/venv/lib/python3.12/site-packages/sqlalchemy/orm/mapper.py", line 2711, in _post_inspect
    self._check_configure()
  File "/Users/gaetanbuelinckx/minutememo_app/venv/lib/python3.12/site-packages/sqlalchemy/orm/mapper.py", line 2388, in _check_configure
    _configure_registries({self.registry}, cascade=True)
  File "/Users/gaetanbuelinckx/minutememo_app/venv/lib/python3.12/site-packages/sqlalchemy/orm/mapper.py", line 4204, in _configure_registries
    _do_configure_registries(registries, cascade)
  File "/Users/gaetanbuelinckx/minutememo_app/venv/lib/python3.12/site-packages/sqlalchemy/orm/mapper.py", line 4241, in _do_configure_registries
    raise e
sqlalchemy.exc.InvalidRequestError: One or more mappers failed to initialize - can't proceed with initialization of other mappers. Triggering mapper: 'Mapper[User(user)]'. Original exception was: When initializing mapper Mapper[User(user)], expression 'meeting_participants' failed to locate a name ("name 'meeting_participants' is not defined"). If this is a class name, consider adding this relationship() to the <class 'models.User'> class after both dependent classes have been defined.
2024-10-13 20:31:53,413 - minutememo_app.app - ERROR - Exception on /auth/status [GET]
Traceback (most recent call last):
  File "/Users/gaetanbuelinckx/minutememo_app/venv/lib/python3.12/site-packages/flask/app.py", line 1473, in wsgi_app
    response = self.full_dispatch_request()
               ^^^^^^^^^^^^^^^^^^^^^^^^^^^^
  File "/Users/gaetanbuelinckx/minutememo_app/venv/lib/python3.12/site-packages/flask/app.py", line 882, in full_dispatch_request
    rv = self.handle_user_exception(e)
         ^^^^^^^^^^^^^^^^^^^^^^^^^^^^^
  File "/Users/gaetanbuelinckx/minutememo_app/venv/lib/python3.12/site-packages/flask_cors/extension.py", line 178, in wrapped_function
    return cors_after_request(app.make_response(f(*args, **kwargs)))
                                                ^^^^^^^^^^^^^^^^^^
  File "/Users/gaetanbuelinckx/minutememo_app/venv/lib/python3.12/site-packages/flask/app.py", line 880, in full_dispatch_request
    rv = self.dispatch_request()
         ^^^^^^^^^^^^^^^^^^^^^^^
  File "/Users/gaetanbuelinckx/minutememo_app/venv/lib/python3.12/site-packages/flask/app.py", line 865, in dispatch_request
    return self.ensure_sync(self.view_functions[rule.endpoint])(**view_args)  # type: ignore[no-any-return]
           ^^^^^^^^^^^^^^^^^^^^^^^^^^^^^^^^^^^^^^^^^^^^^^^^^^^^^^^^^^^^^^^^^
  File "/Users/gaetanbuelinckx/minutememo_app/app.py", line 118, in status
    if current_user.is_authenticated:
       ^^^^^^^^^^^^^^^^^^^^^^^^^^^^^
  File "/Users/gaetanbuelinckx/minutememo_app/venv/lib/python3.12/site-packages/werkzeug/local.py", line 318, in __get__
    obj = instance._get_current_object()
          ^^^^^^^^^^^^^^^^^^^^^^^^^^^^^^
  File "/Users/gaetanbuelinckx/minutememo_app/venv/lib/python3.12/site-packages/werkzeug/local.py", line 526, in _get_current_object
    return get_name(local())
                    ^^^^^^^
  File "/Users/gaetanbuelinckx/minutememo_app/venv/lib/python3.12/site-packages/flask_login/utils.py", line 25, in <lambda>
    current_user = LocalProxy(lambda: _get_user())
                                      ^^^^^^^^^^^
  File "/Users/gaetanbuelinckx/minutememo_app/venv/lib/python3.12/site-packages/flask_login/utils.py", line 370, in _get_user
    current_app.login_manager._load_user()
  File "/Users/gaetanbuelinckx/minutememo_app/venv/lib/python3.12/site-packages/flask_login/login_manager.py", line 364, in _load_user
    user = self._user_callback(user_id)
           ^^^^^^^^^^^^^^^^^^^^^^^^^^^^
  File "/Users/gaetanbuelinckx/minutememo_app/app.py", line 108, in load_user
    return User.query.get(int(user_id))
           ^^^^^^^^^^
  File "/Users/gaetanbuelinckx/minutememo_app/venv/lib/python3.12/site-packages/flask_sqlalchemy/model.py", line 22, in __get__
    return cls.query_class(
           ^^^^^^^^^^^^^^^^
  File "/Users/gaetanbuelinckx/minutememo_app/venv/lib/python3.12/site-packages/sqlalchemy/orm/query.py", line 275, in __init__
    self._set_entities(entities)
  File "/Users/gaetanbuelinckx/minutememo_app/venv/lib/python3.12/site-packages/sqlalchemy/orm/query.py", line 288, in _set_entities
    coercions.expect(
  File "/Users/gaetanbuelinckx/minutememo_app/venv/lib/python3.12/site-packages/sqlalchemy/sql/coercions.py", line 389, in expect
    insp._post_inspect
  File "/Users/gaetanbuelinckx/minutememo_app/venv/lib/python3.12/site-packages/sqlalchemy/util/langhelpers.py", line 1253, in __get__
    obj.__dict__[self.__name__] = result = self.fget(obj)
                                           ^^^^^^^^^^^^^^
  File "/Users/gaetanbuelinckx/minutememo_app/venv/lib/python3.12/site-packages/sqlalchemy/orm/mapper.py", line 2711, in _post_inspect
    self._check_configure()
  File "/Users/gaetanbuelinckx/minutememo_app/venv/lib/python3.12/site-packages/sqlalchemy/orm/mapper.py", line 2388, in _check_configure
    _configure_registries({self.registry}, cascade=True)
  File "/Users/gaetanbuelinckx/minutememo_app/venv/lib/python3.12/site-packages/sqlalchemy/orm/mapper.py", line 4204, in _configure_registries
    _do_configure_registries(registries, cascade)
  File "/Users/gaetanbuelinckx/minutememo_app/venv/lib/python3.12/site-packages/sqlalchemy/orm/mapper.py", line 4241, in _do_configure_registries
    raise e
sqlalchemy.exc.InvalidRequestError: One or more mappers failed to initialize - can't proceed with initialization of other mappers. Triggering mapper: 'Mapper[User(user)]'. Original exception was: When initializing mapper Mapper[User(user)], expression 'meeting_participants' failed to locate a name ("name 'meeting_participants' is not defined"). If this is a class name, consider adding this relationship() to the <class 'models.User'> class after both dependent classes have been defined.
2024-10-13 20:31:53 DEBUG: After request, Origin: http://localhost:3000
2024-10-13 20:31:53,414 - auth - DEBUG - After request, Origin: http://localhost:3000
2024-10-13 20:31:53 INFO: 127.0.0.1 - - [13/Oct/2024 20:31:53] "[35m[1mGET /auth/status HTTP/1.1[0m" 500 -
2024-10-13 20:31:53,414 - werkzeug - INFO - 127.0.0.1 - - [13/Oct/2024 20:31:53] "[35m[1mGET /auth/status HTTP/1.1[0m" 500 -
2024-10-13 20:31:58 ERROR: Exception on /auth/status [GET]
Traceback (most recent call last):
  File "/Users/gaetanbuelinckx/minutememo_app/venv/lib/python3.12/site-packages/flask/app.py", line 1473, in wsgi_app
    response = self.full_dispatch_request()
               ^^^^^^^^^^^^^^^^^^^^^^^^^^^^
  File "/Users/gaetanbuelinckx/minutememo_app/venv/lib/python3.12/site-packages/flask/app.py", line 882, in full_dispatch_request
    rv = self.handle_user_exception(e)
         ^^^^^^^^^^^^^^^^^^^^^^^^^^^^^
  File "/Users/gaetanbuelinckx/minutememo_app/venv/lib/python3.12/site-packages/flask_cors/extension.py", line 178, in wrapped_function
    return cors_after_request(app.make_response(f(*args, **kwargs)))
                                                ^^^^^^^^^^^^^^^^^^
  File "/Users/gaetanbuelinckx/minutememo_app/venv/lib/python3.12/site-packages/flask/app.py", line 880, in full_dispatch_request
    rv = self.dispatch_request()
         ^^^^^^^^^^^^^^^^^^^^^^^
  File "/Users/gaetanbuelinckx/minutememo_app/venv/lib/python3.12/site-packages/flask/app.py", line 865, in dispatch_request
    return self.ensure_sync(self.view_functions[rule.endpoint])(**view_args)  # type: ignore[no-any-return]
           ^^^^^^^^^^^^^^^^^^^^^^^^^^^^^^^^^^^^^^^^^^^^^^^^^^^^^^^^^^^^^^^^^
  File "/Users/gaetanbuelinckx/minutememo_app/app.py", line 118, in status
    if current_user.is_authenticated:
       ^^^^^^^^^^^^^^^^^^^^^^^^^^^^^
  File "/Users/gaetanbuelinckx/minutememo_app/venv/lib/python3.12/site-packages/werkzeug/local.py", line 318, in __get__
    obj = instance._get_current_object()
          ^^^^^^^^^^^^^^^^^^^^^^^^^^^^^^
  File "/Users/gaetanbuelinckx/minutememo_app/venv/lib/python3.12/site-packages/werkzeug/local.py", line 526, in _get_current_object
    return get_name(local())
                    ^^^^^^^
  File "/Users/gaetanbuelinckx/minutememo_app/venv/lib/python3.12/site-packages/flask_login/utils.py", line 25, in <lambda>
    current_user = LocalProxy(lambda: _get_user())
                                      ^^^^^^^^^^^
  File "/Users/gaetanbuelinckx/minutememo_app/venv/lib/python3.12/site-packages/flask_login/utils.py", line 370, in _get_user
    current_app.login_manager._load_user()
  File "/Users/gaetanbuelinckx/minutememo_app/venv/lib/python3.12/site-packages/flask_login/login_manager.py", line 364, in _load_user
    user = self._user_callback(user_id)
           ^^^^^^^^^^^^^^^^^^^^^^^^^^^^
  File "/Users/gaetanbuelinckx/minutememo_app/app.py", line 108, in load_user
    return User.query.get(int(user_id))
           ^^^^^^^^^^
  File "/Users/gaetanbuelinckx/minutememo_app/venv/lib/python3.12/site-packages/flask_sqlalchemy/model.py", line 22, in __get__
    return cls.query_class(
           ^^^^^^^^^^^^^^^^
  File "/Users/gaetanbuelinckx/minutememo_app/venv/lib/python3.12/site-packages/sqlalchemy/orm/query.py", line 275, in __init__
    self._set_entities(entities)
  File "/Users/gaetanbuelinckx/minutememo_app/venv/lib/python3.12/site-packages/sqlalchemy/orm/query.py", line 288, in _set_entities
    coercions.expect(
  File "/Users/gaetanbuelinckx/minutememo_app/venv/lib/python3.12/site-packages/sqlalchemy/sql/coercions.py", line 389, in expect
    insp._post_inspect
  File "/Users/gaetanbuelinckx/minutememo_app/venv/lib/python3.12/site-packages/sqlalchemy/util/langhelpers.py", line 1253, in __get__
    obj.__dict__[self.__name__] = result = self.fget(obj)
                                           ^^^^^^^^^^^^^^
  File "/Users/gaetanbuelinckx/minutememo_app/venv/lib/python3.12/site-packages/sqlalchemy/orm/mapper.py", line 2711, in _post_inspect
    self._check_configure()
  File "/Users/gaetanbuelinckx/minutememo_app/venv/lib/python3.12/site-packages/sqlalchemy/orm/mapper.py", line 2388, in _check_configure
    _configure_registries({self.registry}, cascade=True)
  File "/Users/gaetanbuelinckx/minutememo_app/venv/lib/python3.12/site-packages/sqlalchemy/orm/mapper.py", line 4204, in _configure_registries
    _do_configure_registries(registries, cascade)
  File "/Users/gaetanbuelinckx/minutememo_app/venv/lib/python3.12/site-packages/sqlalchemy/orm/mapper.py", line 4241, in _do_configure_registries
    raise e
sqlalchemy.exc.InvalidRequestError: One or more mappers failed to initialize - can't proceed with initialization of other mappers. Triggering mapper: 'Mapper[User(user)]'. Original exception was: When initializing mapper Mapper[User(user)], expression 'meeting_participants' failed to locate a name ("name 'meeting_participants' is not defined"). If this is a class name, consider adding this relationship() to the <class 'models.User'> class after both dependent classes have been defined.
2024-10-13 20:31:58,380 - minutememo_app.app - ERROR - Exception on /auth/status [GET]
Traceback (most recent call last):
  File "/Users/gaetanbuelinckx/minutememo_app/venv/lib/python3.12/site-packages/flask/app.py", line 1473, in wsgi_app
    response = self.full_dispatch_request()
               ^^^^^^^^^^^^^^^^^^^^^^^^^^^^
  File "/Users/gaetanbuelinckx/minutememo_app/venv/lib/python3.12/site-packages/flask/app.py", line 882, in full_dispatch_request
    rv = self.handle_user_exception(e)
         ^^^^^^^^^^^^^^^^^^^^^^^^^^^^^
  File "/Users/gaetanbuelinckx/minutememo_app/venv/lib/python3.12/site-packages/flask_cors/extension.py", line 178, in wrapped_function
    return cors_after_request(app.make_response(f(*args, **kwargs)))
                                                ^^^^^^^^^^^^^^^^^^
  File "/Users/gaetanbuelinckx/minutememo_app/venv/lib/python3.12/site-packages/flask/app.py", line 880, in full_dispatch_request
    rv = self.dispatch_request()
         ^^^^^^^^^^^^^^^^^^^^^^^
  File "/Users/gaetanbuelinckx/minutememo_app/venv/lib/python3.12/site-packages/flask/app.py", line 865, in dispatch_request
    return self.ensure_sync(self.view_functions[rule.endpoint])(**view_args)  # type: ignore[no-any-return]
           ^^^^^^^^^^^^^^^^^^^^^^^^^^^^^^^^^^^^^^^^^^^^^^^^^^^^^^^^^^^^^^^^^
  File "/Users/gaetanbuelinckx/minutememo_app/app.py", line 118, in status
    if current_user.is_authenticated:
       ^^^^^^^^^^^^^^^^^^^^^^^^^^^^^
  File "/Users/gaetanbuelinckx/minutememo_app/venv/lib/python3.12/site-packages/werkzeug/local.py", line 318, in __get__
    obj = instance._get_current_object()
          ^^^^^^^^^^^^^^^^^^^^^^^^^^^^^^
  File "/Users/gaetanbuelinckx/minutememo_app/venv/lib/python3.12/site-packages/werkzeug/local.py", line 526, in _get_current_object
    return get_name(local())
                    ^^^^^^^
  File "/Users/gaetanbuelinckx/minutememo_app/venv/lib/python3.12/site-packages/flask_login/utils.py", line 25, in <lambda>
    current_user = LocalProxy(lambda: _get_user())
                                      ^^^^^^^^^^^
  File "/Users/gaetanbuelinckx/minutememo_app/venv/lib/python3.12/site-packages/flask_login/utils.py", line 370, in _get_user
    current_app.login_manager._load_user()
  File "/Users/gaetanbuelinckx/minutememo_app/venv/lib/python3.12/site-packages/flask_login/login_manager.py", line 364, in _load_user
    user = self._user_callback(user_id)
           ^^^^^^^^^^^^^^^^^^^^^^^^^^^^
  File "/Users/gaetanbuelinckx/minutememo_app/app.py", line 108, in load_user
    return User.query.get(int(user_id))
           ^^^^^^^^^^
  File "/Users/gaetanbuelinckx/minutememo_app/venv/lib/python3.12/site-packages/flask_sqlalchemy/model.py", line 22, in __get__
    return cls.query_class(
           ^^^^^^^^^^^^^^^^
  File "/Users/gaetanbuelinckx/minutememo_app/venv/lib/python3.12/site-packages/sqlalchemy/orm/query.py", line 275, in __init__
    self._set_entities(entities)
  File "/Users/gaetanbuelinckx/minutememo_app/venv/lib/python3.12/site-packages/sqlalchemy/orm/query.py", line 288, in _set_entities
    coercions.expect(
  File "/Users/gaetanbuelinckx/minutememo_app/venv/lib/python3.12/site-packages/sqlalchemy/sql/coercions.py", line 389, in expect
    insp._post_inspect
  File "/Users/gaetanbuelinckx/minutememo_app/venv/lib/python3.12/site-packages/sqlalchemy/util/langhelpers.py", line 1253, in __get__
    obj.__dict__[self.__name__] = result = self.fget(obj)
                                           ^^^^^^^^^^^^^^
  File "/Users/gaetanbuelinckx/minutememo_app/venv/lib/python3.12/site-packages/sqlalchemy/orm/mapper.py", line 2711, in _post_inspect
    self._check_configure()
  File "/Users/gaetanbuelinckx/minutememo_app/venv/lib/python3.12/site-packages/sqlalchemy/orm/mapper.py", line 2388, in _check_configure
    _configure_registries({self.registry}, cascade=True)
  File "/Users/gaetanbuelinckx/minutememo_app/venv/lib/python3.12/site-packages/sqlalchemy/orm/mapper.py", line 4204, in _configure_registries
    _do_configure_registries(registries, cascade)
  File "/Users/gaetanbuelinckx/minutememo_app/venv/lib/python3.12/site-packages/sqlalchemy/orm/mapper.py", line 4241, in _do_configure_registries
    raise e
sqlalchemy.exc.InvalidRequestError: One or more mappers failed to initialize - can't proceed with initialization of other mappers. Triggering mapper: 'Mapper[User(user)]'. Original exception was: When initializing mapper Mapper[User(user)], expression 'meeting_participants' failed to locate a name ("name 'meeting_participants' is not defined"). If this is a class name, consider adding this relationship() to the <class 'models.User'> class after both dependent classes have been defined.
2024-10-13 20:31:58 DEBUG: After request, Origin: http://localhost:3000
2024-10-13 20:31:58,381 - auth - DEBUG - After request, Origin: http://localhost:3000
2024-10-13 20:31:58 INFO: 127.0.0.1 - - [13/Oct/2024 20:31:58] "[35m[1mGET /auth/status HTTP/1.1[0m" 500 -
2024-10-13 20:31:58,381 - werkzeug - INFO - 127.0.0.1 - - [13/Oct/2024 20:31:58] "[35m[1mGET /auth/status HTTP/1.1[0m" 500 -
2024-10-13 20:31:58 ERROR: Exception on /auth/status [GET]
Traceback (most recent call last):
  File "/Users/gaetanbuelinckx/minutememo_app/venv/lib/python3.12/site-packages/flask/app.py", line 1473, in wsgi_app
    response = self.full_dispatch_request()
               ^^^^^^^^^^^^^^^^^^^^^^^^^^^^
  File "/Users/gaetanbuelinckx/minutememo_app/venv/lib/python3.12/site-packages/flask/app.py", line 882, in full_dispatch_request
    rv = self.handle_user_exception(e)
         ^^^^^^^^^^^^^^^^^^^^^^^^^^^^^
  File "/Users/gaetanbuelinckx/minutememo_app/venv/lib/python3.12/site-packages/flask_cors/extension.py", line 178, in wrapped_function
    return cors_after_request(app.make_response(f(*args, **kwargs)))
                                                ^^^^^^^^^^^^^^^^^^
  File "/Users/gaetanbuelinckx/minutememo_app/venv/lib/python3.12/site-packages/flask/app.py", line 880, in full_dispatch_request
    rv = self.dispatch_request()
         ^^^^^^^^^^^^^^^^^^^^^^^
  File "/Users/gaetanbuelinckx/minutememo_app/venv/lib/python3.12/site-packages/flask/app.py", line 865, in dispatch_request
    return self.ensure_sync(self.view_functions[rule.endpoint])(**view_args)  # type: ignore[no-any-return]
           ^^^^^^^^^^^^^^^^^^^^^^^^^^^^^^^^^^^^^^^^^^^^^^^^^^^^^^^^^^^^^^^^^
  File "/Users/gaetanbuelinckx/minutememo_app/app.py", line 118, in status
    if current_user.is_authenticated:
       ^^^^^^^^^^^^^^^^^^^^^^^^^^^^^
  File "/Users/gaetanbuelinckx/minutememo_app/venv/lib/python3.12/site-packages/werkzeug/local.py", line 318, in __get__
    obj = instance._get_current_object()
          ^^^^^^^^^^^^^^^^^^^^^^^^^^^^^^
  File "/Users/gaetanbuelinckx/minutememo_app/venv/lib/python3.12/site-packages/werkzeug/local.py", line 526, in _get_current_object
    return get_name(local())
                    ^^^^^^^
  File "/Users/gaetanbuelinckx/minutememo_app/venv/lib/python3.12/site-packages/flask_login/utils.py", line 25, in <lambda>
    current_user = LocalProxy(lambda: _get_user())
                                      ^^^^^^^^^^^
  File "/Users/gaetanbuelinckx/minutememo_app/venv/lib/python3.12/site-packages/flask_login/utils.py", line 370, in _get_user
    current_app.login_manager._load_user()
  File "/Users/gaetanbuelinckx/minutememo_app/venv/lib/python3.12/site-packages/flask_login/login_manager.py", line 364, in _load_user
    user = self._user_callback(user_id)
           ^^^^^^^^^^^^^^^^^^^^^^^^^^^^
  File "/Users/gaetanbuelinckx/minutememo_app/app.py", line 108, in load_user
    return User.query.get(int(user_id))
           ^^^^^^^^^^
  File "/Users/gaetanbuelinckx/minutememo_app/venv/lib/python3.12/site-packages/flask_sqlalchemy/model.py", line 22, in __get__
    return cls.query_class(
           ^^^^^^^^^^^^^^^^
  File "/Users/gaetanbuelinckx/minutememo_app/venv/lib/python3.12/site-packages/sqlalchemy/orm/query.py", line 275, in __init__
    self._set_entities(entities)
  File "/Users/gaetanbuelinckx/minutememo_app/venv/lib/python3.12/site-packages/sqlalchemy/orm/query.py", line 288, in _set_entities
    coercions.expect(
  File "/Users/gaetanbuelinckx/minutememo_app/venv/lib/python3.12/site-packages/sqlalchemy/sql/coercions.py", line 389, in expect
    insp._post_inspect
  File "/Users/gaetanbuelinckx/minutememo_app/venv/lib/python3.12/site-packages/sqlalchemy/util/langhelpers.py", line 1253, in __get__
    obj.__dict__[self.__name__] = result = self.fget(obj)
                                           ^^^^^^^^^^^^^^
  File "/Users/gaetanbuelinckx/minutememo_app/venv/lib/python3.12/site-packages/sqlalchemy/orm/mapper.py", line 2711, in _post_inspect
    self._check_configure()
  File "/Users/gaetanbuelinckx/minutememo_app/venv/lib/python3.12/site-packages/sqlalchemy/orm/mapper.py", line 2388, in _check_configure
    _configure_registries({self.registry}, cascade=True)
  File "/Users/gaetanbuelinckx/minutememo_app/venv/lib/python3.12/site-packages/sqlalchemy/orm/mapper.py", line 4204, in _configure_registries
    _do_configure_registries(registries, cascade)
  File "/Users/gaetanbuelinckx/minutememo_app/venv/lib/python3.12/site-packages/sqlalchemy/orm/mapper.py", line 4241, in _do_configure_registries
    raise e
sqlalchemy.exc.InvalidRequestError: One or more mappers failed to initialize - can't proceed with initialization of other mappers. Triggering mapper: 'Mapper[User(user)]'. Original exception was: When initializing mapper Mapper[User(user)], expression 'meeting_participants' failed to locate a name ("name 'meeting_participants' is not defined"). If this is a class name, consider adding this relationship() to the <class 'models.User'> class after both dependent classes have been defined.
2024-10-13 20:31:58 DEBUG: After request, Origin: http://localhost:3000
2024-10-13 20:31:58 INFO: 127.0.0.1 - - [13/Oct/2024 20:31:58] "[35m[1mGET /auth/status HTTP/1.1[0m" 500 -
2024-10-13 20:31:59 DEBUG: Google login initiated. Redirect URI: http://localhost:5000/auth/callback, State: 705cdwY9HmKuCqim-XEqJA
2024-10-13 20:31:59 DEBUG: Client ID: 760628373064-ccotsm9m4l9q81a9e6gmtfj9gjudjpt1.apps.googleusercontent.com
2024-10-13 20:31:59 DEBUG: Session contents: <SecureCookieSession {'_flashes': [('message', 'Please log in to access this page.'), ('message', 'Please log in to access this page.'), ('message', 'Please log in to access this page.'), ('message', 'Please log in to access this page.'), ('message', 'Please log in to access this page.'), ('message', 'Please log in to access this page.'), ('message', 'Please log in to access this page.'), ('message', 'Please log in to access this page.'), ('message', 'Please log in to access this page.'), ('message', 'Please log in to access this page.'), ('message', 'Please log in to access this page.'), ('message', 'Please log in to access this page.'), ('message', 'Please log in to access this page.'), ('message', 'Please log in to access this page.'), ('message', 'Please log in to access this page.')], '_fresh': True, '_id': '80f0c8f52e9d0894341645dd90e6d8ae068eccca8a01568dae0e1571fcf8617cd62df66b248fa262c3936ab84cb81e2f75bd1e859e1c93555c3e41b7cf1c1e14', '_permanent': True, '_user_id': '14', 'oauth_state': '705cdwY9HmKuCqim-XEqJA', 'nonce': 'yLw9KspflXXUz5quU26psw'}>
2024-10-13 20:31:59 DEBUG: After request, Origin: None
2024-10-13 20:31:59 INFO: 127.0.0.1 - - [13/Oct/2024 20:31:59] "[32mGET /auth/login/google HTTP/1.1[0m" 302 -
2024-10-13 20:32:04 DEBUG: Google authorization callback reached
2024-10-13 20:32:04 DEBUG: OAuth state: 705cdwY9HmKuCqim-XEqJA
2024-10-13 20:32:04 DEBUG: Starting new HTTPS connection (1): accounts.google.com:443
2024-10-13 20:32:04 DEBUG: https://accounts.google.com:443 "POST /o/oauth2/token HTTP/11" 200 None
2024-10-13 20:32:04 DEBUG: Starting new HTTPS connection (1): www.googleapis.com:443
2024-10-13 20:32:04 DEBUG: https://www.googleapis.com:443 "GET /oauth2/v3/certs HTTP/11" 200 743
2024-10-13 20:32:04 DEBUG: Token response received: {'access_token': 'ya29.a0AcM612xGm6CCYJ5_VPtNcSggSkMF33o0EgGympa-KGimCaFlP1UIGoLQ_9pBFh8nFEPurs1_VaQeB_ZpkIyAqUWElzo1nou11gaXgeA625M95D6uKThKu3ahq6IvHPgz_VwPEPWZEo9K3WNLjJTtR6o9iDQsv1ZNRDAJQBWKaCgYKAdASARMSFQHGX2MiRZnFzQd9gVkqFJ5Rx4-cqg0175', 'expires_in': 3599, 'refresh_token': '1//03UhnGWTLfpdFCgYIARAAGAMSNwF-L9Ir1NgKVTRhLFDekGYanDyY7iyKMRb3pGpc3x5X1QHmFIkZorPozjE4fIR0lEziVSihNtA', 'scope': 'openid https://www.googleapis.com/auth/calendar https://www.googleapis.com/auth/userinfo.email https://www.googleapis.com/auth/userinfo.profile', 'token_type': 'Bearer', 'id_token': 'eyJhbGciOiJSUzI1NiIsImtpZCI6ImE1MGY2ZTcwZWY0YjU0OGE1ZmQ5MTQyZWVjZDFmYjhmNTRkY2U5ZWUiLCJ0eXAiOiJKV1QifQ.eyJpc3MiOiJhY2NvdW50cy5nb29nbGUuY29tIiwiYXpwIjoiNzYwNjI4MzczMDY0LWNjb3RzbTltNGw5cTgxYTllNmdtdGZqOWdqdWRqcHQxLmFwcHMuZ29vZ2xldXNlcmNvbnRlbnQuY29tIiwiYXVkIjoiNzYwNjI4MzczMDY0LWNjb3RzbTltNGw5cTgxYTllNmdtdGZqOWdqdWRqcHQxLmFwcHMuZ29vZ2xldXNlcmNvbnRlbnQuY29tIiwic3ViIjoiMTA4ODI2NjIyMzE1MDExNzcxMDM2IiwiaGQiOiJtaW51dGVtZW1vLmlvIiwiZW1haWwiOiJnYWV0YW5AbWludXRlbWVtby5pbyIsImVtYWlsX3ZlcmlmaWVkIjp0cnVlLCJhdF9oYXNoIjoiTDFkYlRaR2Rua3FnenRLQXYzemlTUSIsIm5vbmNlIjoieUx3OUtzcGZsWFhVejVxdVUyNnBzdyIsImlhdCI6MTcyODg0NDMyNCwiZXhwIjoxNzI4ODQ3OTI0fQ.N0yo1VqYm3wSf9zR7g-5seTNPD0xza92e4weZDwV-h2h-n1JCCSNYkz5kuDRBL8nkkU0MEE-LE7N8fdPBQ-qDjV_nhqo44vLMnmJSbGb2uRBTyRP1HkIxOaQfg7d6z1yzsPeycNrDw15swo18BEmS-gEjV6dwUwygYOOGu-Yg1VjGh_R4BOUwYU0FIBcncb5jFgyRejpcQS0h_UgztCFcRr2Gc9LEgWQTEVVcD2GsiEJ1iUOaITstR-fiHbTzAJweu8-sAnAmOFK0UYuKeoesieWhuuripMHgNTRxS33zXV1NVq1AZLmXtO9WwIS1anUBbtR0RJjm5kfnNm6z-fuYg', 'expires_at': 1728847923, 'userinfo': {'iss': 'accounts.google.com', 'azp': '760628373064-ccotsm9m4l9q81a9e6gmtfj9gjudjpt1.apps.googleusercontent.com', 'aud': '760628373064-ccotsm9m4l9q81a9e6gmtfj9gjudjpt1.apps.googleusercontent.com', 'sub': '108826622315011771036', 'hd': 'minutememo.io', 'email': 'gaetan@minutememo.io', 'email_verified': True, 'at_hash': 'L1dbTZGdnkqgztKAv3ziSQ', 'nonce': 'yLw9KspflXXUz5quU26psw', 'iat': 1728844324, 'exp': 1728847924}}
2024-10-13 20:32:04 ERROR: Error during Google authorization: OpenIDMixin.parse_id_token() missing 1 required positional argument: 'nonce'
2024-10-13 20:32:04 DEBUG: After request, Origin: None
2024-10-13 20:32:04 INFO: 127.0.0.1 - - [13/Oct/2024 20:32:04] "[35m[1mGET /auth/callback?state=705cdwY9HmKuCqim-XEqJA&code=4/0AVG7fiT2gkQgtULGRCbsfm-diKj4ychqXCee_VhQS5GR5q6eQJJ8KQAX-LH8wye_R_icuw&scope=email%20profile%20openid%20https://www.googleapis.com/auth/userinfo.email%20https://www.googleapis.com/auth/userinfo.profile%20https://www.googleapis.com/auth/calendar&authuser=0&hd=minutememo.io&prompt=consent HTTP/1.1[0m" 500 -
